Workbook

Sheet TRACK
A1: =1000000+SUM(M3:M73) -> 1052540.2 | B1: 46129
B2: Stock | C2: Buy | D2: Sell | E2: Shares0 | F2: Shares | G2: PriceAcq | H2: Amount | I2: % Fund0 | J2: % fund1 | K2: MtM | L2: %perform | M2: Net P&L | N2: Sector
B3: Trade 1 | C3: 45985 | D3: 45995 | F3: 643 | G3: 311 | H3: =+F3*G3 -> 199973 | I3: =+H3/$A$1 -> 0.18999085 | J3: =+K3*F3/$K$91 -> 0.17405161 | K3: 316 | L3: =+K3/G3-1 -> 0.01607717 | M3: =+(K3-G3)*F3 -> 3215
B4: Trade 2 | C4: 45993 | D4: 45995 | F4: 4800 | G4: 40.93 | H4: =+F4*G4 -> 196464 | I4: =+H4/$A$1 -> 0.18665701 | J4: =+K4*F4/$K$91 -> 0.174336 | K4: 42.4 | L4: =+K4/G4-1 -> 0.035914977 | M4: =+(K4-G4)*F4 -> 7056
B5: Trade 3 | C5: 46001 | D5: 46003 | F5: 27000 | G5: 2.02 | H5: =+F5*G5 -> 54540 | I5: =+H5/$A$1 -> 0.0518175 | J5: =+K5*F5/$K$91 -> 0.048569435 | K5: 2.1 | L5: =+K5/G5-1 -> 0.03960396 | M5: =+(K5-G5)*F5 -> 2160
B6: Trade 4 | C6: 46003 | D6: 46003 | F6: 4900 | G6: 11.15 | H6: =+F6*G6 -> 54635 | I6: =+H6/$A$1 -> 0.051907758 | J6: =+K6*F6/$K$91 -> 0.044282133 | K6: 10.55 | L6: =+K6/G6-1 -> -0.053811659 | M6: =+(K6-G6)*F6 -> -2940
B7: Trade 5 | C7: 46002 | D7: 46003 | F7: 470 | G7: 117 | H7: =+F7*G7 -> 54990 | I7: =+H7/$A$1 -> 0.052245038 | J7: =+K7*F7/$K$91 -> 0.04496279 | K7: 111.68 | L7: =+K7/G7-1 -> -0.045470085 | M7: =+(K7-G7)*F7 -> -2500.4
B8: Trade 6 | C8: 46000 | D8: 46003 | F8: 3600 | G8: 15.6 | H8: =+F8*G8 -> 56160 | I8: =+H8/$A$1 -> 0.053356634 | J8: =+K8*F8/$K$91 -> 0.044838069 | K8: 14.54 | L8: =+K8/G8-1 -> -0.067948718 | M8: =+(K8-G8)*F8 -> -3816
B9: Trade 7 | C9: 45981 | D9: 46006 | F9: 2500 | G9: 20.4 | H9: =+F9*G9 -> 51000 | I9: =+H9/$A$1 -> 0.048454208 | J9: =+K9*F9/$K$91 -> 0.037155189 | K9: 17.35 | L9: =+K9/G9-1 -> -0.1495098 | M9: =+(K9-G9)*F9 -> -7625
B10: Trade 8 | C10: 45979 | D10: 46006 | F10: 6400 | G10: 7.87 | H10: =+F10*G10 -> 50368 | I10: =+H10/$A$1 -> 0.047853756 | J10: =+K10*F10/$K$91 -> 0.062114054 | K10: 11.33 | L10: =+K10/G10-1 -> 0.43964422 | M10: =+(K10-G10)*F10 -> 22144
B11: Trade 9 | C11: 45982 | D11: 46007 | F11: 1077 | G11: 92.83 | H11: =+F11*G11 -> 99977.91 | I11: =+H11/$A$1 -> 0.094987264 | J11: =+K11*F11/$K$91 -> 0.082569324 | K11: 89.5 | L11: =+K11/G11-1 -> -0.035872024 | M11: =+(K11-G11)*F11 -> -3586.41
B12: Trade 10 | C12: 45981 | D12: 46007 | F12: 1700 | G12: 30.34 | H12: =+F12*G12 -> 51578 | I12: =+H12/$A$1 -> 0.049003356 | J12: =+K12*F12/$K$91 -> 0.041764574 | K12: 28.68 | L12: =+K12/G12-1 -> -0.05471325 | M12: =+(K12-G12)*F12 -> -2822
B13: Trade 11 | C13: 45980 | D13: 46007 | F13: 600 | G13: 83.4 | H13: =+F13*G13 -> 50040 | I13: =+H13/$A$1 -> 0.047542129 | J13: =+K13*F13/$K$91 -> 0.044596506 | K13: 86.77 | L13: =+K13/G13-1 -> 0.040407674 | M13: =+(K13-G13)*F13 -> 2022
B14: Trade 12 | C14: 45985 | D14: 46008 | F14: =50000/2 -> 25000 | G14: 2 | H14: =+F14*G14 -> 50000 | I14: =+H14/$A$1 -> 0.047504126 | J14: =+K14*F14/$K$91 -> 0.041759435 | K14: 1.95 | L14: =+K14/G14-1 -> -0.025 | M14: =+(K14-G14)*F14 -> -1250
B15: Trade 13 | C15: 45979 | D15: 46008 | F15: 2500 | G15: 19.71 | H15: =+F15*G15 -> 49275 | I15: =+H15/A1 -> 0.046815316 | J15: =+K15*F15/$K$91 -> 0.036662642 | K15: 17.12 | L15: =+K15/G15-1 -> -0.13140538 | M15: =+(K15-G15)*F15 -> -6475
B16: Trade 14 | C16: 46006 | D16: 46024 | F16: =55000/5 -> 11000 | G16: 5 | H16: =+F16*G16 -> 55000 | I16: =+H16/$A$1 -> 0.052254538 | J16: =+K16*F16/$K$91 -> 0.046453623 | K16: 4.93 | L16: =+K16/G16-1 -> -0.014 | M16: =+(K16-G16)*F16 -> -770
B17: Trade 15 | C17: 46009 | D17: 46029 | F17: 2000 | G17: 25.42 | H17: =+F17*G17 -> 50840 | I17: =+H17/$A$1 -> 0.048302195 | J17: =+K17*F17/$K$91 -> 0.037810491 | K17: 22.07 | L17: =+K17/G17-1 -> -0.131786 | M17: =+(K17-G17)*F17 -> -6700
B18: Trade 16 | C18: 45981 | D18: 46031 | F18: 12000 | G18: 4.21 | H18: =+F18*G18 -> 50520 | I18: =+H18/$A$1 -> 0.047998169 | J18: =+K18*F18/$K$91 -> 0.052835321 | K18: 5.14 | L18: =+K18/G18-1 -> 0.22090261 | M18: =+(K18-G18)*F18 -> 11160
B19: Trade 17 | C19: 45980 | D19: 46031 | F19: 12000 | G19: 4.21 | H19: =+F19*G19 -> 50520 | I19: =+H19/$A$1 -> 0.047998169 | J19: =+K19*F19/$K$91 -> 0.051601812 | K19: 5.02 | L19: =+K19/G19-1 -> 0.19239905 | M19: =+(K19-G19)*F19 -> 9720
B20: Trade 18 | C20: 46008 | D20: 46035 | F20: 14000 | G20: 3.91 | H20: =+F20*G20 -> 54740 | I20: =+H20/$A$1 -> 0.052007517 | J20: =+K20*F20/$K$91 -> 0.047610038 | K20: 3.97 | L20: =+K20/G20-1 -> 0.015345269 | M20: =+(K20-G20)*F20 -> 840
B21: Trade 19 | C21: 46036 | D21: 46042 | F21: 2616 | G21: 19.11 | H21: =+F21*G21 -> 49991.76 | I21: =+H21/$A$1 -> 0.047496297 | J21: =+K21*F21/$K$91 -> 0.039484226 | K21: 17.62 | L21: =+K21/G21-1 -> -0.077969649 | M21: =+(K21-G21)*F21 -> -3897.84
B22: Trade 20 | C22: 46002 | D22: 46043 | F22: 1700 | G22: 16 | H22: =+F22*G22 -> 27200 | I22: =+H22/$A$1 -> 0.025842244 | J22: =+K22*F22/$K$91 -> 0.039609359 | K22: 27.2 | L22: =+K22/G22-1 -> 0.7 | M22: =+(K22-G22)*F22 -> 19040
B23: Trade 21 | C23: 46034 | D23: 46049 | F23: =60000+26851 -> 86851 | G23: 1.88 | H23: =+F23*G23 -> 163279.88 | I23: =+H23/$A$1 -> 0.15512936 | J23: =+K23*F23/$K$91 -> 0.12349885 | K23: 1.66 | L23: =+K23/G23-1 -> -0.11702128 | M23: =+(K23-G23)*F23 -> -19107.22
B24: Trade 22 | C24: 46036 | D24: 46050 | F24: 5568 | G24: 8.98 | H24: =+F24*G24 -> 50000.64 | I24: =+H24/$A$1 -> 0.047504734 | J24: =+K24*F24/$K$91 -> 0.039682821 | K24: 8.32 | L24: =+K24/G24-1 -> -0.073496659 | M24: =+(K24-G24)*F24 -> -3674.88
B25: Trade 23 | C25: 46045 | D25: 46050 | F25: =ROUND(50000/G25,0) -> 24631 | G25: 2.03 | H25: =+F25*G25 -> 50000.93 | I25: =+H25/$A$1 -> 0.047505009 | J25: =+K25*F25/$K$91 -> 0.040510095 | K25: 1.92 | L25: =+K25/G25-1 -> -0.054187192 | M25: =+(K25-G25)*F25 -> -2709.41
B26: Trade 24 | C26: 46042 | D26: 46052 | F26: =ROUND(50000/G26,0) -> 18116 | G26: 2.76 | H26: =+F26*G26 -> 50000.16 | I26: =+H26/$A$1 -> 0.047504278 | J26: =+K26*F26/$K$91 -> 0.038485221 | K26: 2.48 | L26: =+K26/G26-1 -> -0.10144928 | M26: =+(K26-G26)*F26 -> -5072.48
B27: Trade 25 | C27: 46031 | D27: 46052 | F27: 2778 | G27: 18 | H27: =+F27*G27 -> 50004 | I27: =+H27/$A$1 -> 0.047507926 | J27: =+K27*F27/$K$91 -> 0.049234862 | K27: 20.69 | L27: =+K27/G27-1 -> 0.14944444 | M27: =+(K27-G27)*F27 -> 7472.82
B28: Trade 26 | C28: 45981 | D28: 46057 | F28: 670 | G28: 74.69 | H28: =+F28*G28 -> 50042.3 | I28: =+H28/$A$1 -> 0.047544314 | J28: =+K28*F28/$K$91 -> 0.044306974 | K28: 77.2 | L28: =+K28/G28-1 -> 0.03360557 | M28: =+(K28-G28)*F28 -> 1681.7
B29: Trade 27 | C29: 45981 | D29: 46057 | F29: 6500 | G29: 7.65 | H29: =+F29*G29 -> 49725 | I29: =+H29/$A$1 -> 0.047242853 | J29: =+K29*F29/$K$91 -> 0.059561374 | K29: =(4300*10.88+2200*10.34)/F29 -> 10.697231 | L29: =+K29/G29-1 -> 0.39833082 | M29: =+(K29-G29)*F29 -> 19807
B30: Trade 28 | C30: 46002 | D30: 46057 | F30: 1700 | G30: 16 | H30: =+F30*G30 -> 27200 | I30: =+H30/$A$1 -> 0.025842244 | J30: =+K30*F30/$K$91 -> 0.033329597 | K30: =+(1000*23.04+700*22.67)/F30 -> 22.887647 | L30: =+K30/G30-1 -> 0.43047794 | M30: =+(K30-G30)*F30 -> 11709
B31: Trade 29 | C31: 46050 | D31: 46057 | F31: 10163 | G31: 4.92 | H31: =+F31*G31 -> 50001.96 | I31: =+H31/$A$1 -> 0.047505988 | J31: =+K31*F31/$K$91 -> 0.039610772 | K31: 4.55 | L31: =+K31/G31-1 -> -0.075203252 | M31: =+(K31-G31)*F31 -> -3760.31
B32: Trade 30 | C32: 46031 | D32: 46057 | F32: =1800+907 -> 2707 | G32: 18.47 | H32: =+F32*G32 -> 49998.29 | I32: =+H32/$A$1 -> 0.047502501 | J32: =+K32*F32/$K$91 -> 0.04370019 | K32: =+(1800*19.01+907*18.52)/F32 -> 18.845822 | L32: =+K32/G32-1 -> 0.020347696 | M32: =+(K32-G32)*F32 -> 1017.35
B33: Trade 31 | C33: 46002 | D33: 46057 | F33: 2300 | G33: 24 | H33: =+F33*G33 -> 55200 | I33: =+H33/$A$1 -> 0.052444555 | J33: =+K33*F33/$K$91 -> 0.049894601 | K33: =+(1500*25.53+800*24.94)/F33 -> 25.324783 | L33: =+K33/G33-1 -> 0.055199275 | M33: =+(K33-G33)*F33 -> 3047
B34: Trade 32 | C34: 46001 | D34: 46057 | F34: 1600 | G34: 34.4 | H34: =+F34*G34 -> 55040 | I34: =+H34/$A$1 -> 0.052292542 | J34: =+K34*F34/$K$91 -> 0.046731163 | K34: =+(1000*34.46+600*33.49)/F34 -> 34.09625 | L34: =+K34/G34-1 -> -0.0088299419 | M34: =+(K34-G34)*F34 -> -486
B35: Trade 33 | C35: 46043 | D35: 46057 | F35: 2200 | G35: 11.4 | H35: =+F35*G35 -> 25080 | I35: =+H35/$A$1 -> 0.02382807 | J35: =+K35*F35/$K$91 -> 0.020880574 | K35: 11.08 | L35: =+K35/G35-1 -> -0.028070175 | M35: =+(K35-G35)*F35 -> -704
B36: Trade 34 | C36: 45979 | D36: 46057 | F36: 11500 | G36: 4.32 | H36: =+F36*G36 -> 49680 | I36: =+H36/$A$1 -> 0.047200099 | J36: =+K36*F36/$K$91 -> 0.054771246 | K36: 5.56 | L36: =+K36/G36-1 -> 0.28703704 | M36: =+(K36-G36)*F36 -> 14260
B37: Trade 35 | C37: 46036 | D37: 46057 | F37: 4558 | G37: 10.97 | H37: =+F37*G37 -> 50001.26 | I37: =+H37/$A$1 -> 0.047505323 | J37: =+K37*F37/$K$91 -> 0.048063165 | K37: 12.31 | L37: =+K37/G37-1 -> 0.12215132 | M37: =+(K37-G37)*F37 -> 6107.72
B38: Trade 36 | C38: 46030 | D38: 46057 | F38: 4634 | G38: 10.79 | H38: =+F38*G38 -> 50000.86 | I38: =+H38/$A$1 -> 0.047504943 | J38: =+K38*F38/$K$91 -> 0.048269144 | K38: 12.16 | L38: =+K38/G38-1 -> 0.12696942 | M38: =+(K38-G38)*F38 -> 6348.58
B39: Trade 37 | C39: 46042 | D39: 46057 | F39: 5952 | G39: 8.4 | H39: =+F39*G39 -> 49996.8 | I39: =+H39/$A$1 -> 0.047501086 | J39: =+K39*F39/$K$91 -> 0.041705777 | K39: 8.18 | L39: =+K39/G39-1 -> -0.026190476 | M39: =+(K39-G39)*F39 -> -1309.44
B40: Trade 38 | C40: 46043 | D40: 46058 | F40: =4386-2200 -> 2186 | G40: 11.4 | H40: =+F40*G40 -> 24920.4 | I40: =+H40/$A$1 -> 0.023676436 | J40: =+K40*F40/$K$91 -> 0.019942507 | K40: 10.65 | L40: =+K40/G40-1 -> -0.065789474 | M40: =+(K40-G40)*F40 -> -1639.5
...

Sheet Portfolio
A2: Date | B2: Invested | C2: Cash | D2: Portoflio | E2: Performance | G2: S&P500
A3: =+Precios!A5 -> 45979 | B3: =+SUM(Value!F7:XFD7) -> 0 | C3: =+Value!D7 -> 1000000 | D3: =+B3+C3 -> 1000000 | G3: 607
A4: =+Precios!A6 -> 45980 | B4: =+SUM(Value!F8:XFD8) -> 0 | C4: =+Value!D8 -> 1000000 | D4: =+B4+C4 -> 1000000 | E4: =+D4/$D$3-1 -> 0 | G4: 609.2
A5: =+Precios!A7 -> 45981 | B5: =+SUM(Value!F9:XFD9) -> 0 | C5: =+Value!D9 -> 1000000 | D5: =+B5+C5 -> 1000000 | E5: =+D5/$D$3-1 -> 0 | G5: 599.96
A6: =+Precios!A8 -> 45982 | B6: =+SUM(Value!F10:XFD10) -> 0 | C6: =+Value!D10 -> 1000000 | D6: =+B6+C6 -> 1000000 | E6: =+D6/$D$3-1 -> 0 | G6: 605.93
A7: =+Precios!A9 -> 45985 | B7: =+SUM(Value!F11:XFD11) -> 0 | C7: =+Value!D11 -> 1000000 | D7: =+B7+C7 -> 1000000 | E7: =+D7/$D$3-1 -> 0 | G7: 614.94
A8: =+Precios!A10 -> 45986 | B8: =+SUM(Value!F12:XFD12) -> 0 | C8: =+Value!D12 -> 1000000 | D8: =+B8+C8 -> 1000000 | E8: =+D8/$D$3-1 -> 0 | G8: 620.66
A9: =+Precios!A11 -> 45987 | B9: =+SUM(Value!F13:XFD13) -> 0 | C9: =+Value!D13 -> 1000000 | D9: =+B9+C9 -> 1000000 | E9: =+D9/$D$3-1 -> 0 | G9: 624.95
A10: =+Precios!A12 -> 45988 | B10: =+SUM(Value!F14:XFD14) -> 0 | C10: =+Value!D14 -> 1000000 | D10: =+B10+C10 -> 1000000 | E10: =+D10/$D$3-1 -> 0 | G10: 628.41
A11: =+Precios!A13 -> 45989 | B11: =+SUM(Value!F15:XFD15) -> 0 | C11: =+Value!D15 -> 1000000 | D11: =+B11+C11 -> 1000000 | E11: =+D11/$D$3-1 -> 0 | G11: 628.41
A12: =+Precios!A14 -> 45992 | B12: =+SUM(Value!F16:XFD16) -> 0 | C12: =+Value!D16 -> 1000000 | D12: =+B12+C12 -> 1000000 | E12: =+D12/$D$3-1 -> 0 | G12: 625.52
A13: =+Precios!A15 -> 45993 | B13: =+SUM(Value!F17:XFD17) -> 0 | C13: =+Value!D17 -> 1000000 | D13: =+B13+C13 -> 1000000 | E13: =+D13/$D$3-1 -> 0 | G13: 626.58
A14: =+Precios!A16 -> 45994 | B14: =+SUM(Value!F18:XFD18) -> 0 | C14: =+Value!D18 -> 1000000 | D14: =+B14+C14 -> 1000000 | E14: =+D14/$D$3-1 -> 0 | G14: 628.77
A15: =+Precios!A17 -> 45995 | B15: =+SUM(Value!F19:XFD19) -> 0 | C15: =+Value!D19 -> 1010271 | D15: =+B15+C15 -> 1010271 | E15: =+D15/$D$3-1 -> 0.010271 | G15: 629.3
... A111: =+Precios!A113 -> 46129 | B111: =+SUM(Value!F115:XFD115) -> 653084.27 | C111: =+Value!D115 -> 514717.76 | D111: =+B111+C111 -> 1167802 | E111: =+D111/$D$3-1 -> 0.16780203 | G111: 652.78

Sheet Precios
A1: BUY | B1: 45985 | C1: 45993 | D1: 46001 | E1: 46003 | F1: 46002 | G1: 46000 | H1: 45981 | I1: 45979 | J1: 45982 | K1: 45981 | L1: 45980 | M1: 45985 | N1: 45979 | O1: 46006 | P1: 46009 | Q1: 45981 | R1: 45980 | S1: 46008 | T1: 46036 | U1: 46002 | V1: 46034 | W1: 46036 | X1: 46045 | Y1: 46042 | Z1: 46031 | AA1: 45979 | AB1: 45981 | AC1: 45981 | AD1: 46001 | AE1: 46002 | AF1: 46002 | AG1: 46030 | AH1: 46036 | AI1: 46031 | AJ1: 46042 | AK1: 46043 | AL1: 46043 | AM1: 46050 | AN1: 46056 | AO1: 46058 | AP1: 46059 | AQ1: 46059 | AR1: 46063 | AS1: 46064 | AT1: 46065 | AU1: 46070 | AV1: 46071 | AW1: 46071 | AX1: 46071 | AY1: 46072 | AZ1: 46072 | BA1: 46073 | BB1: 46079 | BC1: 46084 | BD1: 46086 | BE1: 46090 | BF1: 46090 | BG1: 46093 | BH1: 46097 | BI1: 46100 | BJ1: 46112 | BK1: 46112 | BL1: 46112 | BM1: 46113 | BN1: 46113 | BO1: 46118 | BP1: 46118 | BQ1: 46118 | BR1: 46121 | BS1: 46122 | BT1: 46125 | BU1: 46127
A2: SELL | B2: 45995 | C2: 45995 | D2: 46003 | E2: 46003 | F2: 46003 | G2: 46003 | H2: 46006 | I2: 46006 | J2: 46007 | K2: 46007 | L2: 46007 | M2: 46008 | N2: 46008 | O2: 46024 | P2: 46029 | Q2: 46031 | R2: 46031 | S2: 46035 | T2: 46042 | U2: 46043 | V2: 46049 | W2: 46050 | X2: 46050 | Y2: 46052 | Z2: 46052 | AA2: 46057 | AB2: 46057 | AC2: 46057 | AD2: 46057 | AE2: 46057 | AF2: 46057 | AG2: 46057 | AH2: 46057 | AI2: 46057 | AJ2: 46057 | AK2: 46057 | AL2: 46058 | AM2: 46057 | AN2: 46080 | AO2: 46058 | AP2: 46070 | AQ2: 46064 | AR2: 46064 | AS2: 46070 | AT2: 46084 | AV2: 46084 | AW2: 46078 | AX2: 46084 | AY2: 46084 | AZ2: 46084 | BA2: 46084 | BB2: 46121 | BC2: 46100 | BE2: 46114 | BG2: 46100 | BH2: 46100 | BI2: 46105 | BL2: 46114 | BO2: 46119
A3: Shares | AU3: 4039 | BD3: 14286 | BF3: 1633 | BJ3: 527 | BK3: 321 | BM3: 3693 | BN3: 2588 | BP3: 3243 | BQ3: 5405 | BR3: 7942 | BS3: 328 | BT3: 586 | BU3: 1027
AU4: CGEM | BD4: ALTO | BF4: CAPR | BJ4: MRVL | BK4: LABU | BM4: NTLA | BN4: LUNR | BP4: WULF | BQ4: BCRX | BR4: POET | BS4: ARM | BT4: CAVA | BU4: YOU
A5: 45979 | I5: 7.87 | N5: 19.71 | AA5: 4.32
A6: 45980 | I6: 8.23 | L6: 83.4 | N6: 18.95 | R6: 4.21 | AA6: 4.25
A7: 45981 | H7: 20.4 | I7: 7.44 | K7: 30.34 | L7: 85.65 | N7: 17.81 | Q7: 4.21 | R7: 3.99 | AA7: 4.2 | AB7: 74.69 | AC7: 7.65
A8: 45982 | H8: 17.93 | I8: 7.09 | J8: 92.83 | K8: 31.42 | L8: 93.55 | N8: 17.93 | Q8: 4.19 | R8: 4.19 | AA8: 4.27 | AB8: 67.35 | AC8: 6.74
A9: 45985 | B9: 311 | H9: 18.09 | I9: 7.49 | J9: 111.4 | K9: 31.4 | L9: 111.4 | M9: 2 | N9: 18.09 | Q9: 4.42 | R9: 4.42 | AA9: 4.63 | AB9: 73 | AC9: 8.72
A10: 45986 | B10: 323.64 | H10: 18.65 | I10: 7.39 | J10: 107.69 | K10: 31.51 | L10: 107.69 | M10: 2.04 | N10: 18.65 | Q10: 4.59 | R10: 4.59 | AA10: 4.67 | AB10: 74 | AC10: 8.44
A11: 45987 | B11: 320.28 | H11: 19.23 | I11: 7.68 | J11: 110.16 | K11: 30.86 | L11: 110.16 | M11: 2.08 | N11: 19.23 | Q11: 4.86 | R11: 4.86 | AA11: 4.84 | AB11: 77.53 | AC11: 8.24
A12: 45988 | B12: 320.12 | H12: 20.25 | I12: 7.67 | J12: 110.39 | K12: 31.34 | L12: 110.39 | M12: 2.15 | N12: 20.25 | Q12: 4.74 | R12: 4.74 | AA12: 4.95 | AB12: 78.12 | AC12: 7.9
A13: 45989 | B13: 320.12 | H13: 20.25 | I13: 7.67 | J13: 110.39 | K13: 31.34 | L13: 110.39 | M13: 2.15 | N13: 20.25 | Q13: 4.74 | R13: 4.74 | AA13: 4.95 | AB13: 78.12 | AC13: 7.9
A14: 45992 | B14: 315.12 | H14: 18.55 | I14: 6.73 | J14: 98.27 | K14: 29.53 | L14: 98.27 | M14: 2.09 | N14: 18.55 | Q14: 4.43 | R14: 4.43 | AA14: 4.61 | AB14: 75.27 | AC14: 7.58
A15: 45993 | B15: 316.02 | C15: 40.93 | H15: 18.18 | I15: 6.56 | J15: 97.38 | K15: 28.44 | L15: 97.38 | M15: 2.05 | N15: 18.18 | Q15: 4.06 | R15: 4.06 | AA15: 4.68 | AB15: 72.16 | AC15: 8.07
A16: 45994 | B16: 320.62 | C16: 43.76 | H16: 17.85 | I16: 7.18 | J16: 101.19 | K16: 30.4 | L16: 101.19 | M16: 2.29 | N16: 17.85 | Q16: 4.49 | R16: 4.49 | AA16: 6.01 | AB16: 73.59 | AC16: 8.92
A17: 45995 | B17: 316 | C17: 42.2 | H17: 18.35 | I17: 7.84 | J17: 104.71 | K17: 29.38 | L17: 104.71 | M17: 2.44 | N17: 18.35 | Q17: 5.06 | R17: 5.06 | AA17: 6.37 | AB17: 76.8 | AC17: 9.19
A18: 45996 | H18: 17.58 | I18: 7.8 | J18: 100.98 | K18: 29.38 | L18: 100.98 | M18: 2.37 | N18: 17.58 | Q18: 5.05 | R18: 5.05 | AA18: 6.05 | AB18: 78.97 | AC18: 9.07
A19: 45999 | H19: 18.06 | I19: 8.27 | J19: 99.8 | K19: 30 | L19: 99.8 | M19: 2.42 | N19: 18.06 | Q19: 5.45 | R19: 5.45 | AA19: 6.23 | AB19: 77.17 | AC19: 9.02
A20: 46000 | G20: 15.6 | H20: 17.87 | I20: 7.91 | J20: 97.46 | K20: 29 | L20: 97.46 | M20: 2.45 | N20: 17.87 | Q20: 5.31 | R20: 5.31 | AA20: 6.9 | AB20: 79.17 | AC20: 9.23
A21: 46001 | D21: 2.02 | G21: 15.76 | H21: 18.32 | I21: 8.18 | J21: 94.93 | K21: 29 | L21: 94.93 | M21: 2.36 | N21: 18.32 | Q21: 5.56 | R21: 5.56 | AA21: 7.15 | AB21: 78.37 | AC21: 8.32 | AD21: 34.4
A22: 46002 | D22: 2.2 | F22: 117 | G22: 15.83 | H22: 18.71 | I22: 8.36 | J22: 95.06 | K22: 29 | L22: 95.06 | M22: 2.32 | N22: 18.71 | Q22: 5.76 | R22: 5.76 | U22: 16 | AA22: 7.22 | AB22: 82.01 | AC22: 9.02 | AD22: 39.67 | AE22: 16 | AF22: 24
A23: 46003 | D23: 2.1 | E23: 10.06 | F23: 111.68 | G23: 14.45 | H23: 17.93 | I23: 8.78 | J23: 90.82 | K23: 31 | L23: 90.82 | M23: 2.17 | N23: 17.93 | Q23: 5.79 | R23: 5.79 | U23: 18.24 | AA23: 6.5 | AB23: 77.85 | AC23: 8.75 | AD23: 36.31 | AE23: 18.24 | AF23: 26.42
A24: 46006 | H24: 17.35 | I24: 11.33 | J24: 91.04 | K24: 31 | L24: 91.04 | M24: 2.15 | N24: 17.35 | O24: 5 | Q24: 5.76 | R24: 5.76 | U24: 18.05 | AA24: 5.94 | AB24: 75.07 | AC24: 7.69 | AD24: 36.75 | AE24: 18.05 | AF24: 26
A25: 46007 | J25: 89.5 | K25: 28.68 | L25: 86.77 | M25: 2.1 | N25: 17.54 | O25: 5.17 | Q25: 5.82 | R25: 5.82 | U25: 17.88 | AA25: 6.07 | AB25: 81.36 | AC25: 8.09 | AD25: 34.36 | AE25: 17.88 | AF25: 26.61
A26: 46008 | M26: 1.95 | N26: 17.12 | O26: 5.27 | Q26: 5.44 | R26: 5.44 | S26: 3.91 | U26: 16.47 | AA26: 5.97 | AB26: 79.1 | AC26: 7.37 | AD26: 32.96 | AE26: 16.47 | AF26: 26.98
A27: 46009 | O27: 5.77 | P27: 25.42 | Q27: 5.45 | R27: 5.45 | S27: 4.17 | U27: 17.49 | AA27: 6.13 | AB27: 82.82 | AC27: 7.8 | AD27: 32.87 | AE27: 17.49 | AF27: 26.18
A28: 46010 | O28: 5.6 | P28: 24.49 | Q28: 5.49 | R28: 5.49 | S28: 4.32 | U28: 19.18 | AA28: 6.78 | AB28: 82.61 | AC28: 9.22 | AD28: 33.09 | AE28: 19.18 | AF28: 26.68
A29: 46013 | O29: 5.71 | P29: 27.13 | Q29: 5.86 | R29: 5.86 | S29: 4.38 | U29: 20.6 | AA29: 7.61 | AB29: 82.52 | AC29: 9.27 | AD29: 34.42 | AE29: 20.6 | AF29: 27.54
A30: 46014 | O30: 5.75 | P30: 23.93 | Q30: 5.71 | R30: 5.71 | S30: 4.07 | U30: 20.73 | AA30: 7.15 | AB30: 78.92 | AC30: 8.96 | AD30: 34.2 | AE30: 20.73 | AF30: 26.76
A31: 46015 | O31: 5.87 | P31: 24.36 | Q31: 5.91 | R31: 5.91 | S31: 4.19 | U31: 20.32 | AA31: 7.02 | AB31: 79.8 | AC31: 9.13 | AD31: 33.67 | AE31: 20.32 | AF31: 26.88
A32: 46016 | O32: 5.28 | P32: 24.18 | Q32: 5.83 | R32: 5.83 | S32: 4.16 | U32: 19.36 | AA32: 6.81 | AB32: 74.69 | AC32: 8.48 | AD32: 33.73 | AE32: 19.36 | AF32: 26.16
A33: 46017 | O33: 5.28 | P33: 24.18 | Q33: 5.83 | R33: 5.83 | S33: 4.16 | U33: 19.36 | AA33: 6.81 | AB33: 74.69 | AC33: 8.48 | AD33: 33.73 | AE33: 19.36 | AF33: 26.16
A34: 46020 | O34: 5.21 | P34: 24.31 | Q34: 5.65 | R34: 5.65 | S34: 4.45 | U34: 19.87 | AA34: 6.54 | AB34: 71.32 | AC34: 8.46 | AD34: 32.97 | AE34: 19.87 | AF34: 25.61
A35: 46021 | O35: 5.18 | P35: 23.79 | Q35: 5.66 | R35: 5.66 | S35: 4.26 | U35: 19.74 | AA35: 6.52 | AB35: 71.8 | AC35: 8.99 | AD35: 33.7 | AE35: 19.74 | AF35: 25.35
A36: 46022 | O36: 5.18 | P36: 23.77 | Q36: 5.5 | R36: 5.5 | S36: 4.18 | U36: 19.72 | AA36: 6.33 | AB36: 71.18 | AC36: 9.76 | AD36: 32 | AE36: 19.72 | AF36: 25.42
A37: 46023 | O37: 4.64 | P37: 25.41 | Q37: 5.25 | R37: 5.25 | S37: 4.28 | U37: 20.41 | AA37: 7.16 | AB37: 75.96 | AC37: 11.02 | AD37: 33.41 | AE37: 20.41 | AF37: 25.91
A38: 46024 | O38: 4.93 | P38: 25.41 | Q38: 5.25 | R38: 5.25 | S38: 4.28 | U38: 20.41 | AA38: 7.16 | AB38: 75.96 | AC38: 11.02 | AD38: 33.41 | AE38: 20.41 | AF38: 25.91
A39: 46027 | P39: 25.18 | Q39: 4.89 | R39: 4.89 | S39: 4.18 | U39: 21.39 | AA39: 7.43 | AB39: 76.85 | AC39: 12.53 | AD39: 33.38 | AE39: 21.39 | AF39: 24.97
A40: 46028 | P40: 23.48 | Q40: 5.26 | R40: 5.26 | S40: 4.55 | U40: 21.84 | AA40: 7.35 | AB40: 80.02 | AC40: 12.84 | AD40: 35.2 | AE40: 21.84 | AF40: 25.9
...

Sheet Cost
B1: =+Precios!A1 -> BUY | C1: =+Precios!B1 -> 45985 | D1: =+Precios!C1 -> 45993 | E1: =+Precios!D1 -> 46001 | F1: =+Precios!E1 -> 46003 | G1: =+Precios!F1 -> 46002 | H1: =+Precios!G1 -> 46000 | I1: =+Precios!H1 -> 45981 | ... AU1: =+Precios!AT1 -> 46065 | AV1: 46070 | AW1: =+Precios!AV1 -> 46071 | AX1: =+Precios!AW1 -> 46071 | AY1: =+Precios!AX1 -> 46071 | AZ1: =+Precios!AY1 -> 46072 | BA1: =+Precios!AZ1 -> 46072 | BB1: =+Precios!BA1 -> 46073 | BC1: =+Precios!BB1 -> 46079 | BD1: =+Precios!BC1 -> 46084 | ... BV1: =+Precios!BU1 -> 46127
B2: =+Precios!A2 -> SELL | C2: =+Precios!B2 -> 45995 | D2: =+Precios!C2 -> 45995 | E2: =+Precios!D2 -> 46003 | F2: =+Precios!E2 -> 46003 | G2: =+Precios!F2 -> 46003 | H2: =+Precios!G2 -> 46003 | I2: =+Precios!H2 -> 46006 | ... AU2: =+Precios!AT2 -> 46084 | AW2: =+Precios!AV2 -> 46084 | AX2: =+Precios!AW2 -> 46078 | AY2: =+Precios!AX2 -> 46084 | AZ2: =+Precios!AY2 -> 46084 | BA2: =+Precios!AZ2 -> 46084 | BB2: =+Precios!BA2 -> 46084 | BC2: =+Precios!BB2 -> 46121 | BD2: =+Precios!BC2 -> 46100 | ... BV2: =+Precios!BU2 -> 0
B3: =+Precios!A3 -> Shares | C3: =+Precios!B3 -> 0 | D3: =+Precios!C3 -> 0 | E3: =+Precios!D3 -> 0 | F3: =+Precios!E3 -> 0 | G3: =+Precios!F3 -> 0 | H3: =+Precios!G3 -> 0 | I3: =+Precios!H3 -> 0 | ... AU3: =+Precios!AT3 -> 0 | AV3: 4039 | AW3: =+Precios!AV3 -> 0 | AX3: =+Precios!AW3 -> 0 | AY3: =+Precios!AX3 -> 0 | AZ3: =+Precios!AY3 -> 0 | BA3: =+Precios!AZ3 -> 0 | BB3: =+Precios!BA3 -> 0 | BC3: =+Precios!BB3 -> 0 | BD3: =+Precios!BC3 -> 0 | ... BV3: =+Precios!BU3 -> 1027
AV4: 2019 | BE4: 12143 | BK4: =527-175 -> 352 | BL4: =+BL3-48 -> 273 | BO4: 2200 | BQ4: 2757 | BR4: 3603 | BS4: 6734
BK5: 289 | BL5: =+BL4-32 -> 241 | BS5: =+BS4-792 -> 5942
A6: COST | B6: =+Precios!A4 -> 0 | C6: =+Precios!B4 -> 0 | D6: =+Precios!C4 -> 0 | E6: =+Precios!D4 -> 0 | F6: =+Precios!E4 -> 0 | G6: =+Precios!F4 -> 0 | H6: =+Precios!G4 -> 0 | I6: =+Precios!H4 -> 0 | ... AU6: =+Precios!AT4 -> 0 | AV6: CGEM | AW6: =+Precios!AV4 -> 0 | AX6: =+Precios!AW4 -> 0 | AY6: =+Precios!AX4 -> 0 | AZ6: =+Precios!AY4 -> 0 | BA6: =+Precios!AZ4 -> 0 | BB6: =+Precios!BA4 -> 0 | BC6: =+Precios!BB4 -> 0 | BD6: =+Precios!BC4 -> 0 | ... BV6: =+Precios!BU4 -> YOU
A7: =+SUM(C7:XFD7) -> 0 | B7: =+Precios!A5 -> 45979 | C7: =+Precios!B5*Precios!B$3 -> 0 | D7: =+Precios!C5*Precios!C$3 -> 0 | E7: =+Precios!D5*Precios!D$3 -> 0 | F7: =+Precios!E5*Precios!E$3 -> 0 | G7: =+Precios!F5*Precios!F$3 -> 0 | H7: =+Precios!G5*Precios!G$3 -> 0 | I7: =+Precios!H5*Precios!H$3 -> 0 | J7: =+Precios!I5*Precios!I$3 -> 0 | ... AM7: =+Precios!AL5*Precios!AL$3 -> 0 | AP7: =+Precios!AO5*Precios!AO$3 -> 0 | AQ7: =+Precios!AP5*Precios!AP$3 -> 0 | AR7: =+Precios!AQ5*Precios!AQ$3 -> 0 | AS7: =+Precios!AR5*Precios!AR$3 -> 0 | AT7: =+Precios!AS5*Precios!AS$3 -> 0 | AU7: =+Precios!AT5*Precios!AT$3 -> 0 | AW7: =+Precios!AV5*Precios!AV$3 -> 0 | AX7: =+Precios!AW5*Precios!AW$3 -> 0 | AY7: =+Precios!AX5*Precios!AX$3 -> 0 | AZ7: =+Precios!AY5*Precios!AY$3 -> 0 | BA7: =+Precios!AZ5*Precios!AZ$3 -> 0 | BB7: =+Precios!BA5*Precios!BA$3 -> 0 | BC7: =+Precios!BB5*Precios!BB$3 -> 0 | BD7: =+Precios!BC5*Precios!BC$3 -> 0 | ... BM7: =+Precios!BL5*Precios!BL$3 -> 0
A8: =+SUM(C8:XFD8) -> 0 | B8: =+Precios!A6 -> 45980 | C8: =+Precios!B6*Precios!B$3 -> 0 | D8: =+Precios!C6*Precios!C$3 -> 0 | E8: =+Precios!D6*Precios!D$3 -> 0 | F8: =+Precios!E6*Precios!E$3 -> 0 | G8: =+Precios!F6*Precios!F$3 -> 0 | H8: =+Precios!G6*Precios!G$3 -> 0 | I8: =+Precios!H6*Precios!H$3 -> 0 | J8: =+J7 -> 0 | K8: =+Precios!J6*Precios!J$3 -> 0 | L8: =+Precios!K6*Precios!K$3 -> 0 | M8: =+Precios!L6*Precios!L$3 -> 0 | N8: =+Precios!M6*Precios!M$3 -> 0 | O8: =+O7 -> 0 | P8: =+Precios!O6*Precios!O$3 -> 0 | Q8: =+Precios!P6*Precios!P$3 -> 0 | R8: =+Precios!Q6*Precios!Q$3 -> 0 | S8: =+Precios!R6*Precios!R$3 -> 0 | T8: =+Precios!S6*Precios!S$3 -> 0 | U8: =+Precios!T6*Precios!T$3 -> 0 | V8: =+Precios!U6*Precios!U$3 -> 0 | W8: =+Precios!V6*Precios!V$3 -> 0 | ... AA8: =+Precios!Z6*Precios!Z$3 -> 0 | AB8: =+AB7 -> 0 | AC8: =+Precios!AB6*Precios!AB$3 -> 0 | AD8: =+Precios!AC6*Precios!AC$3 -> 0 | AE8: =+Precios!AD6*Precios!AD$3 -> 0 | AF8: =+Precios!AE6*Precios!AE$3 -> 0 | AG8: =+Precios!AF6*Precios!AF$3 -> 0 | AH8: =+Precios!AG6*Precios!AG$3 -> 0 | AI8: =+Precios!AH6*Precios!AH$3 -> 0 | AJ8: =+Precios!AI6*Precios!AI$3 -> 0 | ... AM8: =+Precios!AL6*Precios!AL$3 -> 0 | AP8: =+Precios!AO6*Precios!AO$3 -> 0 | AQ8: =+Precios!AP6*Precios!AP$3 -> 0 | AR8: =+Precios!AQ6*Precios!AQ$3 -> 0 | AS8: =+Precios!AR6*Precios!AR$3 -> 0 | AT8: =+Precios!AS6*Precios!AS$3 -> 0 | AU8: =+Precios!AT6*Precios!AT$3 -> 0 | AW8: =+Precios!AV6*Precios!AV$3 -> 0 | AX8: =+Precios!AW6*Precios!AW$3 -> 0 | AY8: =+Precios!AX6*Precios!AX$3 -> 0 | AZ8: =+Precios!AY6*Precios!AY$3 -> 0 | BA8: =+Precios!AZ6*Precios!AZ$3 -> 0 | BB8: =+Precios!BA6*Precios!BA$3 -> 0 | BC8: =+Precios!BB6*Precios!BB$3 -> 0 | BD8: =+Precios!BC6*Precios!BC$3 -> 0 | ... BM8: =+Precios!BL6*Precios!BL$3 -> 0
A9: =+SUM(C9:XFD9) -> 0 | B9: =+Precios!A7 -> 45981 | C9: =+Precios!B7*Precios!B$3 -> 0 | D9: =+Precios!C7*Precios!C$3 -> 0 | E9: =+Precios!D7*Precios!D$3 -> 0 | F9: =+Precios!E7*Precios!E$3 -> 0 | G9: =+Precios!F7*Precios!F$3 -> 0 | H9: =+Precios!G7*Precios!G$3 -> 0 | I9: =+Precios!H7*Precios!H$3 -> 0 | J9: =+J8 -> 0 | K9: =+Precios!J7*Precios!J$3 -> 0 | L9: =+Precios!K7*Precios!K$3 -> 0 | M9: =+M8 -> 0 | N9: =+Precios!M7*Precios!M$3 -> 0 | O9: =+O8 -> 0 | P9: =+Precios!O7*Precios!O$3 -> 0 | Q9: =+Precios!P7*Precios!P$3 -> 0 | R9: =+Precios!Q7*Precios!Q$3 -> 0 | S9: =+S8 -> 0 | T9: =+Precios!S7*Precios!S$3 -> 0 | U9: =+Precios!T7*Precios!T$3 -> 0 | V9: =+Precios!U7*Precios!U$3 -> 0 | W9: =+Precios!V7*Precios!V$3 -> 0 | X9: =+Precios!W7*Precios!W$3 -> 0 | Y9: =+Precios!X7*Precios!X$3 -> 0 | Z9: =+Precios!Y7*Precios!Y$3 -> 0 | AA9: =+Precios!Z7*Precios!Z$3 -> 0 | AB9: =+AB8 -> 0 | AC9: =+Precios!AB7*Precios!AB$3 -> 0 | AD9: =+Precios!AC7*Precios!AC$3 -> 0 | AE9: =+Precios!AD7*Precios!AD$3 -> 0 | AF9: =+Precios!AE7*Precios!AE$3 -> 0 | AG9: =+Precios!AF7*Precios!AF$3 -> 0 | AH9: =+Precios!AG7*Precios!AG$3 -> 0 | AI9: =+Precios!AH7*Precios!AH$3 -> 0 | AJ9: =+Precios!AI7*Precios!AI$3 -> 0 | ... AM9: =+Precios!AL7*Precios!AL$3 -> 0 | AP9: =+Precios!AO7*Precios!AO$3 -> 0 | AQ9: =+Precios!AP7*Precios!AP$3 -> 0 | AR9: =+Precios!AQ7*Precios!AQ$3 -> 0 | AS9: =+Precios!AR7*Precios!AR$3 -> 0 | AT9: =+Precios!AS7*Precios!AS$3 -> 0 | AU9: =+Precios!AT7*Precios!AT$3 -> 0 | AW9: =+Precios!AV7*Precios!AV$3 -> 0 | AX9: =+Precios!AW7*Precios!AW$3 -> 0 | AY9: =+Precios!AX7*Precios!AX$3 -> 0 | AZ9: =+Precios!AY7*Precios!AY$3 -> 0 | BA9: =+Precios!AZ7*Precios!AZ$3 -> 0 | BB9: =+Precios!BA7*Precios!BA$3 -> 0 | BC9: =+Precios!BB7*Precios!BB$3 -> 0 | BD9: =+Precios!BC7*Precios!BC$3 -> 0 | ... BM9: =+Precios!BL7*Precios!BL$3 -> 0
A10: =+SUM(C10:XFD10) -> 0 | B10: =+Precios!A8 -> 45982 | C10: =+Precios!B8*Precios!B$3 -> 0 | D10: =+Precios!C8*Precios!C$3 -> 0 | E10: =+Precios!D8*Precios!D$3 -> 0 | F10: =+Precios!E8*Precios!E$3 -> 0 | G10: =+Precios!F8*Precios!F$3 -> 0 | H10: =+Precios!G8*Precios!G$3 -> 0 | I10: =+I9 -> 0 | J10: =+J9 -> 0 | K10: =+Precios!J8*Precios!J$3 -> 0 | L10: =+L9 -> 0 | M10: =+M9 -> 0 | N10: =+Precios!M8*Precios!M$3 -> 0 | O10: =+O9 -> 0 | P10: =+Precios!O8*Precios!O$3 -> 0 | Q10: =+Precios!P8*Precios!P$3 -> 0 | R10: =+R9 -> 0 | S10: =+S9 -> 0 | T10: =+Precios!S8*Precios!S$3 -> 0 | U10: =+Precios!T8*Precios!T$3 -> 0 | V10: =+Precios!U8*Precios!U$3 -> 0 | W10: =+Precios!V8*Precios!V$3 -> 0 | X10: =+Precios!W8*Precios!W$3 -> 0 | Y10: =+Precios!X8*Precios!X$3 -> 0 | Z10: =+Precios!Y8*Precios!Y$3 -> 0 | AA10: =+Precios!Z8*Precios!Z$3 -> 0 | AB10: =+AB9 -> 0 | AC10: =+AC9 -> 0 | AD10: =+AD9 -> 0 | AE10: =+Precios!AD8*Precios!AD$3 -> 0 | AF10: =+Precios!AE8*Precios!AE$3 -> 0 | AG10: =+Precios!AF8*Precios!AF$3 -> 0 | AH10: =+Precios!AG8*Precios!AG$3 -> 0 | AI10: =+Precios!AH8*Precios!AH$3 -> 0 | AJ10: =+Precios!AI8*Precios!AI$3 -> 0 | AK10: =+Precios!AJ8*Precios!AJ$3 -> 0 | AL10: =+Precios!AK8*Precios!AK$3 -> 0 | AM10: =+Precios!AL8*Precios!AL$3 -> 0 | AP10: =+Precios!AO8*Precios!AO$3 -> 0 | AQ10: =+Precios!AP8*Precios!AP$3 -> 0 | AR10: =+Precios!AQ8*Precios!AQ$3 -> 0 | AS10: =+Precios!AR8*Precios!AR$3 -> 0 | AT10: =+Precios!AS8*Precios!AS$3 -> 0 | AU10: =+Precios!AT8*Precios!AT$3 -> 0 | AW10: =+Precios!AV8*Precios!AV$3 -> 0 | AX10: =+Precios!AW8*Precios!AW$3 -> 0 | AY10: =+Precios!AX8*Precios!AX$3 -> 0 | AZ10: =+Precios!AY8*Precios!AY$3 -> 0 | BA10: =+Precios!AZ8*Precios!AZ$3 -> 0 | BB10: =+Precios!BA8*Precios!BA$3 -> 0 | BC10: =+Precios!BB8*Precios!BB$3 -> 0 | BD10: =+Precios!BC8*Precios!BC$3 -> 0 | ... BM10: =+Precios!BL8*Precios!BL$3 -> 0
A11: =+SUM(C11:XFD11) -> 0 | B11: =+Precios!A9 -> 45985 | C11: =+Precios!B9*Precios!B$3 -> 0 | D11: =+Precios!C9*Precios!C$3 -> 0 | E11: =+Precios!D9*Precios!D$3 -> 0 | F11: =+Precios!E9*Precios!E$3 -> 0 | G11: =+Precios!F9*Precios!F$3 -> 0 | H11: =+Precios!G9*Precios!G$3 -> 0 | I11: =+I10 -> 0 | J11: =+J10 -> 0 | K11: =+K10 -> 0 | L11: =+L10 -> 0 | M11: =+M10 -> 0 | N11: =+Precios!M9*Precios!M$3 -> 0 | O11: =+O10 -> 0 | P11: =+Precios!O9*Precios!O$3 -> 0 | Q11: =+Precios!P9*Precios!P$3 -> 0 | R11: =+R10 -> 0 | S11: =+S10 -> 0 | T11: =+Precios!S9*Precios!S$3 -> 0 | U11: =+Precios!T9*Precios!T$3 -> 0 | V11: =+Precios!U9*Precios!U$3 -> 0 | W11: =+Precios!V9*Precios!V$3 -> 0 | X11: =+Precios!W9*Precios!W$3 -> 0 | Y11: =+Precios!X9*Precios!X$3 -> 0 | Z11: =+Precios!Y9*Precios!Y$3 -> 0 | AA11: =+Precios!Z9*Precios!Z$3 -> 0 | AB11: =+AB10 -> 0 | AC11: =+AC10 -> 0 | AD11: =+AD10 -> 0 | AE11: =+Precios!AD9*Precios!AD$3 -> 0 | AF11: =+Precios!AE9*Precios!AE$3 -> 0 | AG11: =+Precios!AF9*Precios!AF$3 -> 0 | AH11: =+Precios!AG9*Precios!AG$3 -> 0 | AI11: =+Precios!AH9*Precios!AH$3 -> 0 | AJ11: =+Precios!AI9*Precios!AI$3 -> 0 | AK11: =+Precios!AJ9*Precios!AJ$3 -> 0 | AL11: =+Precios!AK9*Precios!AK$3 -> 0 | AM11: =+Precios!AL9*Precios!AL$3 -> 0 | AP11: =+Precios!AO9*Precios!AO$3 -> 0 | AQ11: =+Precios!AP9*Precios!AP$3 -> 0 | AR11: =+Precios!AQ9*Precios!AQ$3 -> 0 | AS11: =+Precios!AR9*Precios!AR$3 -> 0 | AT11: =+Precios!AS9*Precios!AS$3 -> 0 | AU11: =+Precios!AT9*Precios!AT$3 -> 0 | AW11: =+Precios!AV9*Precios!AV$3 -> 0 | AX11: =+Precios!AW9*Precios!AW$3 -> 0 | AY11: =+Precios!AX9*Precios!AX$3 -> 0 | AZ11: =+Precios!AY9*Precios!AY$3 -> 0 | BA11: =+Precios!AZ9*Precios!AZ$3 -> 0 | BB11: =+Precios!BA9*Precios!BA$3 -> 0 | BC11: =+Precios!BB9*Precios!BB$3 -> 0 | BD11: =+Precios!BC9*Precios!BC$3 -> 0 | ... BM11: =+Precios!BL9*Precios!BL$3 -> 0
A12: =+SUM(C12:XFD12) -> 0 | B12: =+Precios!A10 -> 45986 | C12: =+C11 -> 0 | D12: =+Precios!C10*Precios!C$3 -> 0 | E12: =+Precios!D10*Precios!D$3 -> 0 | F12: =+Precios!E10*Precios!E$3 -> 0 | G12: =+Precios!F10*Precios!F$3 -> 0 | H12: =+Precios!G10*Precios!G$3 -> 0 | I12: =+I11 -> 0 | J12: =+J11 -> 0 | K12: =+K11 -> 0 | L12: =+L11 -> 0 | M12: =+M11 -> 0 | N12: =+N11 -> 0 | O12: =+O11 -> 0 | P12: =+Precios!O10*Precios!O$3 -> 0 | Q12: =+Precios!P10*Precios!P$3 -> 0 | R12: =+R11 -> 0 | S12: =+S11 -> 0 | T12: =+Precios!S10*Precios!S$3 -> 0 | U12: =+Precios!T10*Precios!T$3 -> 0 | V12: =+Precios!U10*Precios!U$3 -> 0 | W12: =+Precios!V10*Precios!V$3 -> 0 | X12: =+Precios!W10*Precios!W$3 -> 0 | Y12: =+Precios!X10*Precios!X$3 -> 0 | Z12: =+Precios!Y10*Precios!Y$3 -> 0 | AA12: =+Precios!Z10*Precios!Z$3 -> 0 | AB12: =+AB11 -> 0 | AC12: =+AC11 -> 0 | AD12: =+AD11 -> 0 | AE12: =+Precios!AD10*Precios!AD$3 -> 0 | AF12: =+Precios!AE10*Precios!AE$3 -> 0 | AG12: =+Precios!AF10*Precios!AF$3 -> 0 | AH12: =+Precios!AG10*Precios!AG$3 -> 0 | AI12: =+Precios!AH10*Precios!AH$3 -> 0 | AJ12: =+Precios!AI10*Precios!AI$3 -> 0 | AK12: =+Precios!AJ10*Precios!AJ$3 -> 0 | AL12: =+Precios!AK10*Precios!AK$3 -> 0 | AM12: =+Precios!AL10*Precios!AL$3 -> 0 | AP12: =+Precios!AO10*Precios!AO$3 -> 0 | AQ12: =+Precios!AP10*Precios!AP$3 -> 0 | AR12: =+Precios!AQ10*Precios!AQ$3 -> 0 | AS12: =+Precios!AR10*Precios!AR$3 -> 0 | AT12: =+Precios!AS10*Precios!AS$3 -> 0 | AU12: =+Precios!AT10*Precios!AT$3 -> 0 | AW12: =+Precios!AV10*Precios!AV$3 -> 0 | AX12: =+Precios!AW10*Precios!AW$3 -> 0 | AY12: =+Precios!AX10*Precios!AX$3 -> 0 | AZ12: =+Precios!AY10*Precios!AY$3 -> 0 | BA12: =+Precios!AZ10*Precios!AZ$3 -> 0 | BB12: =+Precios!BA10*Precios!BA$3 -> 0 | BC12: =+Precios!BB10*Precios!BB$3 -> 0 | BD12: =+Precios!BC10*Precios!BC$3 -> 0 | ... BM12: =+Precios!BL10*Precios!BL$3 -> 0
A13: =+SUM(C13:XFD13) -> 0 | B13: =+Precios!A11 -> 45987 | C13: =+C12 -> 0 | D13: =+Precios!C11*Precios!C$3 -> 0 | E13: =+Precios!D11*Precios!D$3 -> 0 | F13: =+Precios!E11*Precios!E$3 -> 0 | G13: =+Precios!F11*Precios!F$3 -> 0 | H13: =+Precios!G11*Precios!G$3 -> 0 | I13: =+I12 -> 0 | J13: =+J12 -> 0 | K13: =+K12 -> 0 | L13: =+L12 -> 0 | M13: =+M12 -> 0 | N13: =+N12 -> 0 | O13: =+O12 -> 0 | P13: =+Precios!O11*Precios!O$3 -> 0 | Q13: =+Precios!P11*Precios!P$3 -> 0 | R13: =+R12 -> 0 | S13: =+S12 -> 0 | T13: =+Precios!S11*Precios!S$3 -> 0 | U13: =+Precios!T11*Precios!T$3 -> 0 | V13: =+Precios!U11*Precios!U$3 -> 0 | W13: =+Precios!V11*Precios!V$3 -> 0 | X13: =+Precios!W11*Precios!W$3 -> 0 | Y13: =+Precios!X11*Precios!X$3 -> 0 | Z13: =+Precios!Y11*Precios!Y$3 -> 0 | AA13: =+Precios!Z11*Precios!Z$3 -> 0 | AB13: =+AB12 -> 0 | AC13: =+AC12 -> 0 | AD13: =+AD12 -> 0 | AE13: =+Precios!AD11*Precios!AD$3 -> 0 | AF13: =+Precios!AE11*Precios!AE$3 -> 0 | AG13: =+Precios!AF11*Precios!AF$3 -> 0 | AH13: =+Precios!AG11*Precios!AG$3 -> 0 | AI13: =+Precios!AH11*Precios!AH$3 -> 0 | AJ13: =+Precios!AI11*Precios!AI$3 -> 0 | AK13: =+Precios!AJ11*Precios!AJ$3 -> 0 | AL13: =+Precios!AK11*Precios!AK$3 -> 0 | AM13: =+Precios!AL11*Precios!AL$3 -> 0 | AP13: =+Precios!AO11*Precios!AO$3 -> 0 | AQ13: =+Precios!AP11*Precios!AP$3 -> 0 | AR13: =+Precios!AQ11*Precios!AQ$3 -> 0 | AS13: =+Precios!AR11*Precios!AR$3 -> 0 | AT13: =+Precios!AS11*Precios!AS$3 -> 0 | AU13: =+Precios!AT11*Precios!AT$3 -> 0 | AW13: =+Precios!AV11*Precios!AV$3 -> 0 | AX13: =+Precios!AW11*Precios!AW$3 -> 0 | AY13: =+Precios!AX11*Precios!AX$3 -> 0 | AZ13: =+Precios!AY11*Precios!AY$3 -> 0 | BA13: =+Precios!AZ11*Precios!AZ$3 -> 0 | BB13: =+Precios!BA11*Precios!BA$3 -> 0 | BC13: =+Precios!BB11*Precios!BB$3 -> 0 | BD13: =+Precios!BC11*Precios!BC$3 -> 0 | ... BM13: =+Precios!BL11*Precios!BL$3 -> 0
A14: =+SUM(C14:XFD14) -> 0 | B14: =+Precios!A12 -> 45988 | C14: =+C13 -> 0 | D14: =+Precios!C12*Precios!C$3 -> 0 | E14: =+Precios!D12*Precios!D$3 -> 0 | F14: =+Precios!E12*Precios!E$3 -> 0 | G14: =+Precios!F12*Precios!F$3 -> 0 | H14: =+Precios!G12*Precios!G$3 -> 0 | I14: =+I13 -> 0 | J14: =+J13 -> 0 | K14: =+K13 -> 0 | L14: =+L13 -> 0 | M14: =+M13 -> 0 | N14: =+N13 -> 0 | O14: =+O13 -> 0 | P14: =+Precios!O12*Precios!O$3 -> 0 | Q14: =+Precios!P12*Precios!P$3 -> 0 | R14: =+R13 -> 0 | S14: =+S13 -> 0 | T14: =+Precios!S12*Precios!S$3 -> 0 | U14: =+Precios!T12*Precios!T$3 -> 0 | V14: =+Precios!U12*Precios!U$3 -> 0 | W14: =+Precios!V12*Precios!V$3 -> 0 | X14: =+Precios!W12*Precios!W$3 -> 0 | Y14: =+Precios!X12*Precios!X$3 -> 0 | Z14: =+Precios!Y12*Precios!Y$3 -> 0 | AA14: =+Precios!Z12*Precios!Z$3 -> 0 | AB14: =+AB13 -> 0 | AC14: =+AC13 -> 0 | AD14: =+AD13 -> 0 | AE14: =+Precios!AD12*Precios!AD$3 -> 0 | AF14: =+Precios!AE12*Precios!AE$3 -> 0 | AG14: =+Precios!AF12*Precios!AF$3 -> 0 | AH14: =+Precios!AG12*Precios!AG$3 -> 0 | AI14: =+Precios!AH12*Precios!AH$3 -> 0 | AJ14: =+Precios!AI12*Precios!AI$3 -> 0 | AK14: =+Precios!AJ12*Precios!AJ$3 -> 0 | AL14: =+Precios!AK12*Precios!AK$3 -> 0 | AM14: =+Precios!AL12*Precios!AL$3 -> 0 | AP14: =+Precios!AO12*Precios!AO$3 -> 0 | AQ14: =+Precios!AP12*Precios!AP$3 -> 0 | AR14: =+Precios!AQ12*Precios!AQ$3 -> 0 | AS14: =+Precios!AR12*Precios!AR$3 -> 0 | AT14: =+Precios!AS12*Precios!AS$3 -> 0 | AU14: =+Precios!AT12*Precios!AT$3 -> 0 | AW14: =+Precios!AV12*Precios!AV$3 -> 0 | AX14: =+Precios!AW12*Precios!AW$3 -> 0 | AY14: =+Precios!AX12*Precios!AX$3 -> 0 | AZ14: =+Precios!AY12*Precios!AY$3 -> 0 | BA14: =+Precios!AZ12*Precios!AZ$3 -> 0 | BB14: =+Precios!BA12*Precios!BA$3 -> 0 | BC14: =+Precios!BB12*Precios!BB$3 -> 0 | BD14: =+Precios!BC12*Precios!BC$3 -> 0 | ... BM14: =+Precios!BL12*Precios!BL$3 -> 0
A15: =+SUM(C15:XFD15) -> 0 | B15: =+Precios!A13 -> 45989 | C15: =+C14 -> 0 | D15: =+Precios!C13*Precios!C$3 -> 0 | E15: =+Precios!D13*Precios!D$3 -> 0 | F15: =+Precios!E13*Precios!E$3 -> 0 | G15: =+Precios!F13*Precios!F$3 -> 0 | H15: =+Precios!G13*Precios!G$3 -> 0 | I15: =+I14 -> 0 | J15: =+J14 -> 0 | K15: =+K14 -> 0 | L15: =+L14 -> 0 | M15: =+M14 -> 0 | N15: =+N14 -> 0 | O15: =+O14 -> 0 | P15: =+Precios!O13*Precios!O$3 -> 0 | Q15: =+Precios!P13*Precios!P$3 -> 0 | R15: =+R14 -> 0 | S15: =+S14 -> 0 | T15: =+Precios!S13*Precios!S$3 -> 0 | U15: =+Precios!T13*Precios!T$3 -> 0 | V15: =+Precios!U13*Precios!U$3 -> 0 | W15: =+Precios!V13*Precios!V$3 -> 0 | X15: =+Precios!W13*Precios!W$3 -> 0 | Y15: =+Precios!X13*Precios!X$3 -> 0 | Z15: =+Precios!Y13*Precios!Y$3 -> 0 | AA15: =+Precios!Z13*Precios!Z$3 -> 0 | AB15: =+AB14 -> 0 | AC15: =+AC14 -> 0 | AD15: =+AD14 -> 0 | AE15: =+Precios!AD13*Precios!AD$3 -> 0 | AF15: =+Precios!AE13*Precios!AE$3 -> 0 | AG15: =+Precios!AF13*Precios!AF$3 -> 0 | AH15: =+Precios!AG13*Precios!AG$3 -> 0 | AI15: =+Precios!AH13*Precios!AH$3 -> 0 | AJ15: =+Precios!AI13*Precios!AI$3 -> 0 | AK15: =+Precios!AJ13*Precios!AJ$3 -> 0 | AL15: =+Precios!AK13*Precios!AK$3 -> 0 | AM15: =+Precios!AL13*Precios!AL$3 -> 0 | AP15: =+Precios!AO13*Precios!AO$3 -> 0 | AQ15: =+Precios!AP13*Precios!AP$3 -> 0 | AR15: =+Precios!AQ13*Precios!AQ$3 -> 0 | AS15: =+Precios!AR13*Precios!AR$3 -> 0 | AT15: =+Precios!AS13*Precios!AS$3 -> 0 | AU15: =+Precios!AT13*Precios!AT$3 -> 0 | AW15: =+Precios!AV13*Precios!AV$3 -> 0 | AX15: =+Precios!AW13*Precios!AW$3 -> 0 | AY15: =+Precios!AX13*Precios!AX$3 -> 0 | AZ15: =+Precios!AY13*Precios!AY$3 -> 0 | BA15: =+Precios!AZ13*Precios!AZ$3 -> 0 | BB15: =+Precios!BA13*Precios!BA$3 -> 0 | BC15: =+Precios!BB13*Precios!BB$3 -> 0 | BD15: =+Precios!BC13*Precios!BC$3 -> 0 | ... BM15: =+Precios!BL13*Precios!BL$3 -> 0
A16: =+SUM(C16:XFD16) -> 0 | B16: =+Precios!A14 -> 45992 | C16: =+C15 -> 0 | D16: =+Precios!C14*Precios!C$3 -> 0 | E16: =+Precios!D14*Precios!D$3 -> 0 | F16: =+Precios!E14*Precios!E$3 -> 0 | G16: =+Precios!F14*Precios!F$3 -> 0 | H16: =+Precios!G14*Precios!G$3 -> 0 | I16: =+I15 -> 0 | J16: =+J15 -> 0 | K16: =+K15 -> 0 | L16: =+L15 -> 0 | M16: =+M15 -> 0 | N16: =+N15 -> 0 | O16: =+O15 -> 0 | P16: =+Precios!O14*Precios!O$3 -> 0 | Q16: =+Precios!P14*Precios!P$3 -> 0 | R16: =+R15 -> 0 | S16: =+S15 -> 0 | T16: =+Precios!S14*Precios!S$3 -> 0 | U16: =+Precios!T14*Precios!T$3 -> 0 | V16: =+Precios!U14*Precios!U$3 -> 0 | W16: =+Precios!V14*Precios!V$3 -> 0 | X16: =+Precios!W14*Precios!W$3 -> 0 | Y16: =+Precios!X14*Precios!X$3 -> 0 | Z16: =+Precios!Y14*Precios!Y$3 -> 0 | AA16: =+Precios!Z14*Precios!Z$3 -> 0 | AB16: =+AB15 -> 0 | AC16: =+AC15 -> 0 | AD16: =+AD15 -> 0 | AE16: =+Precios!AD14*Precios!AD$3 -> 0 | AF16: =+Precios!AE14*Precios!AE$3 -> 0 | AG16: =+Precios!AF14*Precios!AF$3 -> 0 | AH16: =+Precios!AG14*Precios!AG$3 -> 0 | AI16: =+Precios!AH14*Precios!AH$3 -> 0 | AJ16: =+Precios!AI14*Precios!AI$3 -> 0 | AK16: =+Precios!AJ14*Precios!AJ$3 -> 0 | AL16: =+Precios!AK14*Precios!AK$3 -> 0 | AM16: =+Precios!AL14*Precios!AL$3 -> 0 | AP16: =+Precios!AO14*Precios!AO$3 -> 0 | AQ16: =+Precios!AP14*Precios!AP$3 -> 0 | AR16: =+Precios!AQ14*Precios!AQ$3 -> 0 | AS16: =+Precios!AR14*Precios!AR$3 -> 0 | AT16: =+Precios!AS14*Precios!AS$3 -> 0 | AU16: =+Precios!AT14*Precios!AT$3 -> 0 | AW16: =+Precios!AV14*Precios!AV$3 -> 0 | AX16: =+Precios!AW14*Precios!AW$3 -> 0 | AY16: =+Precios!AX14*Precios!AX$3 -> 0 | AZ16: =+Precios!AY14*Precios!AY$3 -> 0 | BA16: =+Precios!AZ14*Precios!AZ$3 -> 0 | BB16: =+Precios!BA14*Precios!BA$3 -> 0 | BC16: =+Precios!BB14*Precios!BB$3 -> 0 | BD16: =+Precios!BC14*Precios!BC$3 -> 0 | ... BM16: =+Precios!BL14*Precios!BL$3 -> 0
A17: =+SUM(C17:XFD17) -> 0 | B17: =+Precios!A15 -> 45993 | C17: =+C16 -> 0 | D17: =+Precios!C15*Precios!C$3 -> 0 | E17: =+Precios!D15*Precios!D$3 -> 0 | F17: =+Precios!E15*Precios!E$3 -> 0 | G17: =+Precios!F15*Precios!F$3 -> 0 | H17: =+Precios!G15*Precios!G$3 -> 0 | I17: =+I16 -> 0 | J17: =+J16 -> 0 | K17: =+K16 -> 0 | L17: =+L16 -> 0 | M17: =+M16 -> 0 | N17: =+N16 -> 0 | O17: =+O16 -> 0 | P17: =+Precios!O15*Precios!O$3 -> 0 | Q17: =+Precios!P15*Precios!P$3 -> 0 | R17: =+R16 -> 0 | S17: =+S16 -> 0 | T17: =+Precios!S15*Precios!S$3 -> 0 | U17: =+Precios!T15*Precios!T$3 -> 0 | V17: =+Precios!U15*Precios!U$3 -> 0 | W17: =+Precios!V15*Precios!V$3 -> 0 | X17: =+Precios!W15*Precios!W$3 -> 0 | Y17: =+Precios!X15*Precios!X$3 -> 0 | Z17: =+Precios!Y15*Precios!Y$3 -> 0 | AA17: =+Precios!Z15*Precios!Z$3 -> 0 | AB17: =+AB16 -> 0 | AC17: =+AC16 -> 0 | AD17: =+AD16 -> 0 | AE17: =+Precios!AD15*Precios!AD$3 -> 0 | AF17: =+Precios!AE15*Precios!AE$3 -> 0 | AG17: =+Precios!AF15*Precios!AF$3 -> 0 | AH17: =+Precios!AG15*Precios!AG$3 -> 0 | AI17: =+Precios!AH15*Precios!AH$3 -> 0 | AJ17: =+Precios!AI15*Precios!AI$3 -> 0 | AK17: =+Precios!AJ15*Precios!AJ$3 -> 0 | AL17: =+Precios!AK15*Precios!AK$3 -> 0 | AM17: =+Precios!AL15*Precios!AL$3 -> 0 | AP17: =+Precios!AO15*Precios!AO$3 -> 0 | AQ17: =+Precios!AP15*Precios!AP$3 -> 0 | AR17: =+Precios!AQ15*Precios!AQ$3 -> 0 | AS17: =+Precios!AR15*Precios!AR$3 -> 0 | AT17: =+Precios!AS15*Precios!AS$3 -> 0 | AU17: =+Precios!AT15*Precios!AT$3 -> 0 | AW17: =+Precios!AV15*Precios!AV$3 -> 0 | AX17: =+Precios!AW15*Precios!AW$3 -> 0 | AY17: =+Precios!AX15*Precios!AX$3 -> 0 | AZ17: =+Precios!AY15*Precios!AY$3 -> 0 | BA17: =+Precios!AZ15*Precios!AZ$3 -> 0 | BB17: =+Precios!BA15*Precios!BA$3 -> 0 | BC17: =+Precios!BB15*Precios!BB$3 -> 0 | BD17: =+Precios!BC15*Precios!BC$3 -> 0 | ... BM17: =+Precios!BL15*Precios!BL$3 -> 0
A18: =+SUM(C18:XFD18) -> 0 | B18: =+Precios!A16 -> 45994 | C18: =+C17 -> 0 | D18: =+D17 -> 0 | E18: =+Precios!D16*Precios!D$3 -> 0 | F18: =+Precios!E16*Precios!E$3 -> 0 | G18: =+Precios!F16*Precios!F$3 -> 0 | H18: =+Precios!G16*Precios!G$3 -> 0 | I18: =+I17 -> 0 | J18: =+J17 -> 0 | K18: =+K17 -> 0 | L18: =+L17 -> 0 | M18: =+M17 -> 0 | N18: =+N17 -> 0 | O18: =+O17 -> 0 | P18: =+Precios!O16*Precios!O$3 -> 0 | Q18: =+Precios!P16*Precios!P$3 -> 0 | R18: =+R17 -> 0 | S18: =+S17 -> 0 | T18: =+Precios!S16*Precios!S$3 -> 0 | U18: =+Precios!T16*Precios!T$3 -> 0 | V18: =+Precios!U16*Precios!U$3 -> 0 | W18: =+Precios!V16*Precios!V$3 -> 0 | X18: =+Precios!W16*Precios!W$3 -> 0 | Y18: =+Precios!X16*Precios!X$3 -> 0 | Z18: =+Precios!Y16*Precios!Y$3 -> 0 | AA18: =+Precios!Z16*Precios!Z$3 -> 0 | AB18: =+AB17 -> 0 | AC18: =+AC17 -> 0 | AD18: =+AD17 -> 0 | AE18: =+Precios!AD16*Precios!AD$3 -> 0 | AF18: =+Precios!AE16*Precios!AE$3 -> 0 | AG18: =+Precios!AF16*Precios!AF$3 -> 0 | AH18: =+Precios!AG16*Precios!AG$3 -> 0 | AI18: =+Precios!AH16*Precios!AH$3 -> 0 | AJ18: =+Precios!AI16*Precios!AI$3 -> 0 | AK18: =+Precios!AJ16*Precios!AJ$3 -> 0 | AL18: =+Precios!AK16*Precios!AK$3 -> 0 | AM18: =+Precios!AL16*Precios!AL$3 -> 0 | AP18: =+Precios!AO16*Precios!AO$3 -> 0 | AQ18: =+Precios!AP16*Precios!AP$3 -> 0 | AR18: =+Precios!AQ16*Precios!AQ$3 -> 0 | AS18: =+Precios!AR16*Precios!AR$3 -> 0 | AT18: =+Precios!AS16*Precios!AS$3 -> 0 | AU18: =+Precios!AT16*Precios!AT$3 -> 0 | AW18: =+Precios!AV16*Precios!AV$3 -> 0 | AX18: =+Precios!AW16*Precios!AW$3 -> 0 | AY18: =+Precios!AX16*Precios!AX$3 -> 0 | AZ18: =+Precios!AY16*Precios!AY$3 -> 0 | BA18: =+Precios!AZ16*Precios!AZ$3 -> 0 | BB18: =+Precios!BA16*Precios!BA$3 -> 0 | BC18: =+Precios!BB16*Precios!BB$3 -> 0 | BD18: =+Precios!BC16*Precios!BC$3 -> 0 | ... BM18: =+Precios!BL16*Precios!BL$3 -> 0
A19: =+SUM(C19:XFD19) -> 0 | B19: =+Precios!A17 -> 45995 | C19: =+C18 -> 0 | D19: =+D18 -> 0 | E19: =+Precios!D17*Precios!D$3 -> 0 | F19: =+Precios!E17*Precios!E$3 -> 0 | G19: =+Precios!F17*Precios!F$3 -> 0 | H19: =+Precios!G17*Precios!G$3 -> 0 | I19: =+I18 -> 0 | J19: =+J18 -> 0 | K19: =+K18 -> 0 | L19: =+L18 -> 0 | M19: =+M18 -> 0 | N19: =+N18 -> 0 | O19: =+O18 -> 0 | P19: =+Precios!O17*Precios!O$3 -> 0 | Q19: =+Precios!P17*Precios!P$3 -> 0 | R19: =+R18 -> 0 | S19: =+S18 -> 0 | T19: =+Precios!S17*Precios!S$3 -> 0 | U19: =+Precios!T17*Precios!T$3 -> 0 | V19: =+Precios!U17*Precios!U$3 -> 0 | W19: =+Precios!V17*Precios!V$3 -> 0 | X19: =+Precios!W17*Precios!W$3 -> 0 | Y19: =+Precios!X17*Precios!X$3 -> 0 | Z19: =+Precios!Y17*Precios!Y$3 -> 0 | AA19: =+Precios!Z17*Precios!Z$3 -> 0 | AB19: =+AB18 -> 0 | AC19: =+AC18 -> 0 | AD19: =+AD18 -> 0 | AE19: =+Precios!AD17*Precios!AD$3 -> 0 | AF19: =+Precios!AE17*Precios!AE$3 -> 0 | AG19: =+Precios!AF17*Precios!AF$3 -> 0 | AH19: =+Precios!AG17*Precios!AG$3 -> 0 | AI19: =+Precios!AH17*Precios!AH$3 -> 0 | AJ19: =+Precios!AI17*Precios!AI$3 -> 0 | AK19: =+Precios!AJ17*Precios!AJ$3 -> 0 | AL19: =+Precios!AK17*Precios!AK$3 -> 0 | AM19: =+Precios!AL17*Precios!AL$3 -> 0 | AP19: =+Precios!AO17*Precios!AO$3 -> 0 | AQ19: =+Precios!AP17*Precios!AP$3 -> 0 | AR19: =+Precios!AQ17*Precios!AQ$3 -> 0 | AS19: =+Precios!AR17*Precios!AR$3 -> 0 | AT19: =+Precios!AS17*Precios!AS$3 -> 0 | AU19: =+Precios!AT17*Precios!AT$3 -> 0 | AW19: =+Precios!AV17*Precios!AV$3 -> 0 | AX19: =+Precios!AW17*Precios!AW$3 -> 0 | AY19: =+Precios!AX17*Precios!AX$3 -> 0 | AZ19: =+Precios!AY17*Precios!AY$3 -> 0 | BA19: =+Precios!AZ17*Precios!AZ$3 -> 0 | BB19: =+Precios!BA17*Precios!BA$3 -> 0 | BC19: =+Precios!BB17*Precios!BB$3 -> 0 | BD19: =+Precios!BC17*Precios!BC$3 -> 0 | ... BM19: =+Precios!BL17*Precios!BL$3 -> 0
A20: =+SUM(C20:XFD20) -> 0 | B20: =+Precios!A18 -> 45996 | C20: =+Precios!B18*Precios!B$3 -> 0 | D20: =+Precios!C18*Precios!C$3 -> 0 | E20: =+Precios!D18*Precios!D$3 -> 0 | F20: =+Precios!E18*Precios!E$3 -> 0 | G20: =+Precios!F18*Precios!F$3 -> 0 | H20: =+Precios!G18*Precios!G$3 -> 0 | I20: =+I19 -> 0 | J20: =+J19 -> 0 | K20: =+K19 -> 0 | L20: =+L19 -> 0 | M20: =+M19 -> 0 | N20: =+N19 -> 0 | O20: =+O19 -> 0 | P20: =+Precios!O18*Precios!O$3 -> 0 | Q20: =+Precios!P18*Precios!P$3 -> 0 | R20: =+R19 -> 0 | S20: =+S19 -> 0 | T20: =+Precios!S18*Precios!S$3 -> 0 | U20: =+Precios!T18*Precios!T$3 -> 0 | V20: =+Precios!U18*Precios!U$3 -> 0 | W20: =+Precios!V18*Precios!V$3 -> 0 | X20: =+Precios!W18*Precios!W$3 -> 0 | Y20: =+Precios!X18*Precios!X$3 -> 0 | Z20: =+Precios!Y18*Precios!Y$3 -> 0 | AA20: =+Precios!Z18*Precios!Z$3 -> 0 | AB20: =+AB19 -> 0 | AC20: =+AC19 -> 0 | AD20: =+AD19 -> 0 | AE20: =+Precios!AD18*Precios!AD$3 -> 0 | AF20: =+Precios!AE18*Precios!AE$3 -> 0 | AG20: =+Precios!AF18*Precios!AF$3 -> 0 | AH20: =+Precios!AG18*Precios!AG$3 -> 0 | AI20: =+Precios!AH18*Precios!AH$3 -> 0 | AJ20: =+Precios!AI18*Precios!AI$3 -> 0 | AK20: =+Precios!AJ18*Precios!AJ$3 -> 0 | AL20: =+Precios!AK18*Precios!AK$3 -> 0 | AM20: =+Precios!AL18*Precios!AL$3 -> 0 | AP20: =+Precios!AO18*Precios!AO$3 -> 0 | AQ20: =+Precios!AP18*Precios!AP$3 -> 0 | AR20: =+Precios!AQ18*Precios!AQ$3 -> 0 | AS20: =+Precios!AR18*Precios!AR$3 -> 0 | AT20: =+Precios!AS18*Precios!AS$3 -> 0 | AU20: =+Precios!AT18*Precios!AT$3 -> 0 | AW20: =+Precios!AV18*Precios!AV$3 -> 0 | AX20: =+Precios!AW18*Precios!AW$3 -> 0 | AY20: =+Precios!AX18*Precios!AX$3 -> 0 | AZ20: =+Precios!AY18*Precios!AY$3 -> 0 | BA20: =+Precios!AZ18*Precios!AZ$3 -> 0 | BB20: =+Precios!BA18*Precios!BA$3 -> 0 | BC20: =+Precios!BB18*Precios!BB$3 -> 0 | BD20: =+Precios!BC18*Precios!BC$3 -> 0 | ... BM20: =+Precios!BL18*Precios!BL$3 -> 0
A21: =+SUM(C21:XFD21) -> 0 | B21: =+Precios!A19 -> 45999 | C21: =+Precios!B19*Precios!B$3 -> 0 | D21: =+Precios!C19*Precios!C$3 -> 0 | E21: =+Precios!D19*Precios!D$3 -> 0 | F21: =+Precios!E19*Precios!E$3 -> 0 | G21: =+Precios!F19*Precios!F$3 -> 0 | H21: =+Precios!G19*Precios!G$3 -> 0 | I21: =+I20 -> 0 | J21: =+J20 -> 0 | K21: =+K20 -> 0 | L21: =+L20 -> 0 | M21: =+M20 -> 0 | N21: =+N20 -> 0 | O21: =+O20 -> 0 | P21: =+Precios!O19*Precios!O$3 -> 0 | Q21: =+Precios!P19*Precios!P$3 -> 0 | R21: =+R20 -> 0 | S21: =+S20 -> 0 | T21: =+Precios!S19*Precios!S$3 -> 0 | U21: =+Precios!T19*Precios!T$3 -> 0 | V21: =+Precios!U19*Precios!U$3 -> 0 | W21: =+Precios!V19*Precios!V$3 -> 0 | X21: =+Precios!W19*Precios!W$3 -> 0 | Y21: =+Precios!X19*Precios!X$3 -> 0 | Z21: =+Precios!Y19*Precios!Y$3 -> 0 | AA21: =+Precios!Z19*Precios!Z$3 -> 0 | AB21: =+AB20 -> 0 | AC21: =+AC20 -> 0 | AD21: =+AD20 -> 0 | AE21: =+Precios!AD19*Precios!AD$3 -> 0 | AF21: =+Precios!AE19*Precios!AE$3 -> 0 | AG21: =+Precios!AF19*Precios!AF$3 -> 0 | AH21: =+Precios!AG19*Precios!AG$3 -> 0 | AI21: =+Precios!AH19*Precios!AH$3 -> 0 | AJ21: =+Precios!AI19*Precios!AI$3 -> 0 | AK21: =+Precios!AJ19*Precios!AJ$3 -> 0 | AL21: =+Precios!AK19*Precios!AK$3 -> 0 | AM21: =+Precios!AL19*Precios!AL$3 -> 0 | AP21: =+Precios!AO19*Precios!AO$3 -> 0 | AQ21: =+Precios!AP19*Precios!AP$3 -> 0 | AR21: =+Precios!AQ19*Precios!AQ$3 -> 0 | AS21: =+Precios!AR19*Precios!AR$3 -> 0 | AT21: =+Precios!AS19*Precios!AS$3 -> 0 | AU21: =+Precios!AT19*Precios!AT$3 -> 0 | AW21: =+Precios!AV19*Precios!AV$3 -> 0 | AX21: =+Precios!AW19*Precios!AW$3 -> 0 | AY21: =+Precios!AX19*Precios!AX$3 -> 0 | AZ21: =+Precios!AY19*Precios!AY$3 -> 0 | BA21: =+Precios!AZ19*Precios!AZ$3 -> 0 | BB21: =+Precios!BA19*Precios!BA$3 -> 0 | BC21: =+Precios!BB19*Precios!BB$3 -> 0 | BD21: =+Precios!BC19*Precios!BC$3 -> 0 | ... BM21: =+Precios!BL19*Precios!BL$3 -> 0
A22: =+SUM(C22:XFD22) -> 0 | B22: =+Precios!A20 -> 46000 | C22: =+Precios!B20*Precios!B$3 -> 0 | D22: =+Precios!C20*Precios!C$3 -> 0 | E22: =+Precios!D20*Precios!D$3 -> 0 | F22: =+Precios!E20*Precios!E$3 -> 0 | G22: =+Precios!F20*Precios!F$3 -> 0 | H22: =+Precios!G20*Precios!G$3 -> 0 | I22: =+I21 -> 0 | J22: =+J21 -> 0 | K22: =+K21 -> 0 | L22: =+L21 -> 0 | M22: =+M21 -> 0 | N22: =+N21 -> 0 | O22: =+O21 -> 0 | P22: =+Precios!O20*Precios!O$3 -> 0 | Q22: =+Precios!P20*Precios!P$3 -> 0 | R22: =+R21 -> 0 | S22: =+S21 -> 0 | T22: =+Precios!S20*Precios!S$3 -> 0 | U22: =+Precios!T20*Precios!T$3 -> 0 | V22: =+Precios!U20*Precios!U$3 -> 0 | W22: =+Precios!V20*Precios!V$3 -> 0 | X22: =+Precios!W20*Precios!W$3 -> 0 | Y22: =+Precios!X20*Precios!X$3 -> 0 | Z22: =+Precios!Y20*Precios!Y$3 -> 0 | AA22: =+Precios!Z20*Precios!Z$3 -> 0 | AB22: =+AB21 -> 0 | AC22: =+AC21 -> 0 | AD22: =+AD21 -> 0 | AE22: =+Precios!AD20*Precios!AD$3 -> 0 | AF22: =+Precios!AE20*Precios!AE$3 -> 0 | AG22: =+Precios!AF20*Precios!AF$3 -> 0 | AH22: =+Precios!AG20*Precios!AG$3 -> 0 | AI22: =+Precios!AH20*Precios!AH$3 -> 0 | AJ22: =+Precios!AI20*Precios!AI$3 -> 0 | AK22: =+Precios!AJ20*Precios!AJ$3 -> 0 | AL22: =+Precios!AK20*Precios!AK$3 -> 0 | AM22: =+Precios!AL20*Precios!AL$3 -> 0 | AP22: =+Precios!AO20*Precios!AO$3 -> 0 | AQ22: =+Precios!AP20*Precios!AP$3 -> 0 | AR22: =+Precios!AQ20*Precios!AQ$3 -> 0 | AS22: =+Precios!AR20*Precios!AR$3 -> 0 | AT22: =+Precios!AS20*Precios!AS$3 -> 0 | AU22: =+Precios!AT20*Precios!AT$3 -> 0 | AW22: =+Precios!AV20*Precios!AV$3 -> 0 | AX22: =+Precios!AW20*Precios!AW$3 -> 0 | AY22: =+Precios!AX20*Precios!AX$3 -> 0 | AZ22: =+Precios!AY20*Precios!AY$3 -> 0 | BA22: =+Precios!AZ20*Precios!AZ$3 -> 0 | BB22: =+Precios!BA20*Precios!BA$3 -> 0 | BC22: =+Precios!BB20*Precios!BB$3 -> 0 | BD22: =+Precios!BC20*Precios!BC$3 -> 0 | ... BM22: =+Precios!BL20*Precios!BL$3 -> 0
A23: =+SUM(C23:XFD23) -> 0 | B23: =+Precios!A21 -> 46001 | C23: =+Precios!B21*Precios!B$3 -> 0 | D23: =+Precios!C21*Precios!C$3 -> 0 | E23: =+Precios!D21*Precios!D$3 -> 0 | F23: =+Precios!E21*Precios!E$3 -> 0 | G23: =+Precios!F21*Precios!F$3 -> 0 | H23: =+H22 -> 0 | I23: =+I22 -> 0 | J23: =+J22 -> 0 | K23: =+K22 -> 0 | L23: =+L22 -> 0 | M23: =+M22 -> 0 | N23: =+N22 -> 0 | O23: =+O22 -> 0 | P23: =+Precios!O21*Precios!O$3 -> 0 | Q23: =+Precios!P21*Precios!P$3 -> 0 | R23: =+R22 -> 0 | S23: =+S22 -> 0 | T23: =+Precios!S21*Precios!S$3 -> 0 | U23: =+Precios!T21*Precios!T$3 -> 0 | V23: =+Precios!U21*Precios!U$3 -> 0 | W23: =+Precios!V21*Precios!V$3 -> 0 | X23: =+Precios!W21*Precios!W$3 -> 0 | Y23: =+Precios!X21*Precios!X$3 -> 0 | Z23: =+Precios!Y21*Precios!Y$3 -> 0 | AA23: =+Precios!Z21*Precios!Z$3 -> 0 | AB23: =+AB22 -> 0 | AC23: =+AC22 -> 0 | AD23: =+AD22 -> 0 | AE23: =+Precios!AD21*Precios!AD$3 -> 0 | AF23: =+Precios!AE21*Precios!AE$3 -> 0 | AG23: =+Precios!AF21*Precios!AF$3 -> 0 | AH23: =+Precios!AG21*Precios!AG$3 -> 0 | AI23: =+Precios!AH21*Precios!AH$3 -> 0 | AJ23: =+Precios!AI21*Precios!AI$3 -> 0 | AK23: =+Precios!AJ21*Precios!AJ$3 -> 0 | AL23: =+Precios!AK21*Precios!AK$3 -> 0 | AM23: =+Precios!AL21*Precios!AL$3 -> 0 | AP23: =+Precios!AO21*Precios!AO$3 -> 0 | AQ23: =+Precios!AP21*Precios!AP$3 -> 0 | AR23: =+Precios!AQ21*Precios!AQ$3 -> 0 | AS23: =+Precios!AR21*Precios!AR$3 -> 0 | AT23: =+Precios!AS21*Precios!AS$3 -> 0 | AU23: =+Precios!AT21*Precios!AT$3 -> 0 | AW23: =+Precios!AV21*Precios!AV$3 -> 0 | AX23: =+Precios!AW21*Precios!AW$3 -> 0 | AY23: =+Precios!AX21*Precios!AX$3 -> 0 | AZ23: =+Precios!AY21*Precios!AY$3 -> 0 | BA23: =+Precios!AZ21*Precios!AZ$3 -> 0 | BB23: =+Precios!BA21*Precios!BA$3 -> 0 | BC23: =+Precios!BB21*Precios!BB$3 -> 0 | BD23: =+Precios!BC21*Precios!BC$3 -> 0 | ... BM23: =+Precios!BL21*Precios!BL$3 -> 0
A24: =+SUM(C24:XFD24) -> 0 | B24: =+Precios!A22 -> 46002 | C24: =+Precios!B22*Precios!B$3 -> 0 | D24: =+Precios!C22*Precios!C$3 -> 0 | E24: =+E23 -> 0 | F24: =+Precios!E22*Precios!E$3 -> 0 | G24: =+Precios!F22*Precios!F$3 -> 0 | H24: =+H23 -> 0 | I24: =+I23 -> 0 | J24: =+J23 -> 0 | K24: =+K23 -> 0 | L24: =+L23 -> 0 | M24: =+M23 -> 0 | N24: =+N23 -> 0 | O24: =+O23 -> 0 | P24: =+Precios!O22*Precios!O$3 -> 0 | Q24: =+Precios!P22*Precios!P$3 -> 0 | R24: =+R23 -> 0 | S24: =+S23 -> 0 | T24: =+Precios!S22*Precios!S$3 -> 0 | U24: =+Precios!T22*Precios!T$3 -> 0 | V24: =+Precios!U22*Precios!U$3 -> 0 | W24: =+Precios!V22*Precios!V$3 -> 0 | X24: =+Precios!W22*Precios!W$3 -> 0 | Y24: =+Precios!X22*Precios!X$3 -> 0 | Z24: =+Precios!Y22*Precios!Y$3 -> 0 | AA24: =+Precios!Z22*Precios!Z$3 -> 0 | AB24: =+AB23 -> 0 | AC24: =+AC23 -> 0 | AD24: =+AD23 -> 0 | AE24: =+AE23 -> 0 | AF24: =+Precios!AE22*Precios!AE$3 -> 0 | AG24: =+Precios!AF22*Precios!AF$3 -> 0 | AH24: =+Precios!AG22*Precios!AG$3 -> 0 | AI24: =+Precios!AH22*Precios!AH$3 -> 0 | AJ24: =+Precios!AI22*Precios!AI$3 -> 0 | AK24: =+Precios!AJ22*Precios!AJ$3 -> 0 | AL24: =+Precios!AK22*Precios!AK$3 -> 0 | AM24: =+Precios!AL22*Precios!AL$3 -> 0 | AP24: =+Precios!AO22*Precios!AO$3 -> 0 | AQ24: =+Precios!AP22*Precios!AP$3 -> 0 | AR24: =+Precios!AQ22*Precios!AQ$3 -> 0 | AS24: =+Precios!AR22*Precios!AR$3 -> 0 | AT24: =+Precios!AS22*Precios!AS$3 -> 0 | AU24: =+Precios!AT22*Precios!AT$3 -> 0 | AW24: =+Precios!AV22*Precios!AV$3 -> 0 | AX24: =+Precios!AW22*Precios!AW$3 -> 0 | AY24: =+Precios!AX22*Precios!AX$3 -> 0 | AZ24: =+Precios!AY22*Precios!AY$3 -> 0 | BA24: =+Precios!AZ22*Precios!AZ$3 -> 0 | BB24: =+Precios!BA22*Precios!BA$3 -> 0 | BC24: =+Precios!BB22*Precios!BB$3 -> 0 | BD24: =+Precios!BC22*Precios!BC$3 -> 0 | ... BM24: =+Precios!BL22*Precios!BL$3 -> 0
A25: =+SUM(C25:XFD25) -> 0 | B25: =+Precios!A23 -> 46003 | C25: =+Precios!B23*Precios!B$3 -> 0 | D25: =+Precios!C23*Precios!C$3 -> 0 | E25: =+E24 -> 0 | F25: =+Precios!E23*Precios!E$3 -> 0 | G25: =+G24 -> 0 | H25: =+H24 -> 0 | I25: =+I24 -> 0 | J25: =+J24 -> 0 | K25: =+K24 -> 0 | L25: =+L24 -> 0 | M25: =+M24 -> 0 | N25: =+N24 -> 0 | O25: =+O24 -> 0 | P25: =+Precios!O23*Precios!O$3 -> 0 | Q25: =+Precios!P23*Precios!P$3 -> 0 | R25: =+R24 -> 0 | S25: =+S24 -> 0 | T25: =+Precios!S23*Precios!S$3 -> 0 | U25: =+Precios!T23*Precios!T$3 -> 0 | V25: =+V24 -> 0 | W25: =+Precios!V23*Precios!V$3 -> 0 | X25: =+Precios!W23*Precios!W$3 -> 0 | Y25: =+Precios!X23*Precios!X$3 -> 0 | Z25: =+Precios!Y23*Precios!Y$3 -> 0 | AA25: =+Precios!Z23*Precios!Z$3 -> 0 | AB25: =+AB24 -> 0 | AC25: =+AC24 -> 0 | AD25: =+AD24 -> 0 | AE25: =+AE24 -> 0 | AF25: =+AF24 -> 0 | AG25: =+AG24 -> 0 | AH25: =+Precios!AG23*Precios!AG$3 -> 0 | AI25: =+Precios!AH23*Precios!AH$3 -> 0 | AJ25: =+Precios!AI23*Precios!AI$3 -> 0 | AK25: =+Precios!AJ23*Precios!AJ$3 -> 0 | AL25: =+Precios!AK23*Precios!AK$3 -> 0 | AM25: =+Precios!AL23*Precios!AL$3 -> 0 | AP25: =+Precios!AO23*Precios!AO$3 -> 0 | AQ25: =+Precios!AP23*Precios!AP$3 -> 0 | AR25: =+Precios!AQ23*Precios!AQ$3 -> 0 | AS25: =+Precios!AR23*Precios!AR$3 -> 0 | AT25: =+Precios!AS23*Precios!AS$3 -> 0 | AU25: =+Precios!AT23*Precios!AT$3 -> 0 | AW25: =+Precios!AV23*Precios!AV$3 -> 0 | AX25: =+Precios!AW23*Precios!AW$3 -> 0 | AY25: =+Precios!AX23*Precios!AX$3 -> 0 | AZ25: =+Precios!AY23*Precios!AY$3 -> 0 | BA25: =+Precios!AZ23*Precios!AZ$3 -> 0 | BB25: =+Precios!BA23*Precios!BA$3 -> 0 | BC25: =+Precios!BB23*Precios!BB$3 -> 0 | BD25: =+Precios!BC23*Precios!BC$3 -> 0 | ... BM25: =+Precios!BL23*Precios!BL$3 -> 0
A26: =+SUM(C26:XFD26) -> 0 | B26: =+Precios!A24 -> 46006 | C26: =+Precios!B24*Precios!B$3 -> 0 | D26: =+Precios!C24*Precios!C$3 -> 0 | E26: =+Precios!D24*Precios!D$3 -> 0 | F26: =+Precios!E24*Precios!E$3 -> 0 | G26: =+Precios!F24*Precios!F$3 -> 0 | H26: =+Precios!G24*Precios!G$3 -> 0 | I26: =+I25 -> 0 | J26: =+J25 -> 0 | K26: =+K25 -> 0 | L26: =+L25 -> 0 | M26: =+M25 -> 0 | N26: =+N25 -> 0 | O26: =+O25 -> 0 | P26: =+Precios!O24*Precios!O$3 -> 0 | Q26: =+Precios!P24*Precios!P$3 -> 0 | R26: =+R25 -> 0 | S26: =+S25 -> 0 | T26: =+Precios!S24*Precios!S$3 -> 0 | U26: =+Precios!T24*Precios!T$3 -> 0 | V26: =+V25 -> 0 | W26: =+Precios!V24*Precios!V$3 -> 0 | X26: =+Precios!W24*Precios!W$3 -> 0 | Y26: =+Precios!X24*Precios!X$3 -> 0 | Z26: =+Precios!Y24*Precios!Y$3 -> 0 | AA26: =+Precios!Z24*Precios!Z$3 -> 0 | AB26: =+AB25 -> 0 | AC26: =+AC25 -> 0 | AD26: =+AD25 -> 0 | AE26: =+AE25 -> 0 | AF26: =+AF25 -> 0 | AG26: =+AG25 -> 0 | AH26: =+Precios!AG24*Precios!AG$3 -> 0 | AI26: =+Precios!AH24*Precios!AH$3 -> 0 | AJ26: =+Precios!AI24*Precios!AI$3 -> 0 | AK26: =+Precios!AJ24*Precios!AJ$3 -> 0 | AL26: =+Precios!AK24*Precios!AK$3 -> 0 | AM26: =+Precios!AL24*Precios!AL$3 -> 0 | AP26: =+Precios!AO24*Precios!AO$3 -> 0 | AQ26: =+Precios!AP24*Precios!AP$3 -> 0 | AR26: =+Precios!AQ24*Precios!AQ$3 -> 0 | AS26: =+Precios!AR24*Precios!AR$3 -> 0 | AT26: =+Precios!AS24*Precios!AS$3 -> 0 | AU26: =+Precios!AT24*Precios!AT$3 -> 0 | AW26: =+Precios!AV24*Precios!AV$3 -> 0 | AX26: =+Precios!AW24*Precios!AW$3 -> 0 | AY26: =+Precios!AX24*Precios!AX$3 -> 0 | AZ26: =+Precios!AY24*Precios!AY$3 -> 0 | BA26: =+Precios!AZ24*Precios!AZ$3 -> 0 | BB26: =+Precios!BA24*Precios!BA$3 -> 0 | BC26: =+Precios!BB24*Precios!BB$3 -> 0 | BD26: =+Precios!BC24*Precios!BC$3 -> 0 | ... BM26: =+Precios!BL24*Precios!BL$3 -> 0
A27: =+SUM(C27:XFD27) -> 0 | B27: =+Precios!A25 -> 46007 | C27: =+Precios!B25*Precios!B$3 -> 0 | D27: =+Precios!C25*Precios!C$3 -> 0 | E27: =+Precios!D25*Precios!D$3 -> 0 | F27: =+Precios!E25*Precios!E$3 -> 0 | G27: =+Precios!F25*Precios!F$3 -> 0 | H27: =+Precios!G25*Precios!G$3 -> 0 | I27: =+Precios!H25*Precios!H$3 -> 0 | J27: =+Precios!I25*Precios!I$3 -> 0 | K27: =+K26 -> 0 | L27: =+L26 -> 0 | M27: =+M26 -> 0 | N27: =+N26 -> 0 | O27: =+O26 -> 0 | P27: =+P26 -> 0 | Q27: =+Precios!P25*Precios!P$3 -> 0 | R27: =+R26 -> 0 | S27: =+S26 -> 0 | T27: =+Precios!S25*Precios!S$3 -> 0 | U27: =+Precios!T25*Precios!T$3 -> 0 | V27: =+V26 -> 0 | W27: =+Precios!V25*Precios!V$3 -> 0 | X27: =+Precios!W25*Precios!W$3 -> 0 | Y27: =+Precios!X25*Precios!X$3 -> 0 | Z27: =+Precios!Y25*Precios!Y$3 -> 0 | AA27: =+Precios!Z25*Precios!Z$3 -> 0 | AB27: =+AB26 -> 0 | AC27: =+AC26 -> 0 | AD27: =+AD26 -> 0 | AE27: =+AE26 -> 0 | AF27: =+AF26 -> 0 | AG27: =+AG26 -> 0 | AH27: =+Precios!AG25*Precios!AG$3 -> 0 | AI27: =+Precios!AH25*Precios!AH$3 -> 0 | AJ27: =+Precios!AI25*Precios!AI$3 -> 0 | AK27: =+Precios!AJ25*Precios!AJ$3 -> 0 | AL27: =+Precios!AK25*Precios!AK$3 -> 0 | AM27: =+Precios!AL25*Precios!AL$3 -> 0 | AP27: =+Precios!AO25*Precios!AO$3 -> 0 | AQ27: =+Precios!AP25*Precios!AP$3 -> 0 | AR27: =+Precios!AQ25*Precios!AQ$3 -> 0 | AS27: =+Precios!AR25*Precios!AR$3 -> 0 | AT27: =+Precios!AS25*Precios!AS$3 -> 0 | AU27: =+Precios!AT25*Precios!AT$3 -> 0 | AW27: =+Precios!AV25*Precios!AV$3 -> 0 | AX27: =+Precios!AW25*Precios!AW$3 -> 0 | AY27: =+Precios!AX25*Precios!AX$3 -> 0 | AZ27: =+Precios!AY25*Precios!AY$3 -> 0 | BA27: =+Precios!AZ25*Precios!AZ$3 -> 0 | BB27: =+Precios!BA25*Precios!BA$3 -> 0 | BC27: =+Precios!BB25*Precios!BB$3 -> 0 | BD27: =+Precios!BC25*Precios!BC$3 -> 0 | ... BM27: =+Precios!BL25*Precios!BL$3 -> 0
